Workbook
Name Client: #REF!
Name Client: #REF!
Name Description: #REF!
Name Description: #REF!
Name OrderNumber: #REF!
Name OrderNumber: #REF!
Name PONumber: #REF!
Name PONumber: #REF!
Name Project: #REF!
Name Project: #REF!
Name SIL: #REF!
Name SIL: #REF!

Sheet Cover Sheet
A1: Doc Title: | C1: HeXI I/O Schedule
A2: Doc No: | C2: C15862H-HEXI-IOS | G2: Rev: | H2: 0/2
A3: Client: | C3: Diamond Light Source Limited
A4: Project: | C4: HIMax System
A5: Description: | C5: Safety Instrumented System for Three Flagship Beamlines and HeXI | I5: SC Ref:
A6: PO No: | C6: 9001537/8046970/9003503 | I6: C15862H
A25: B10 E - HeXI Safety Instrumented System
A29: I/O Schedule
B45: 0/2 | C45: 46128 | D45: Client Mods | I45: CW
B46: 0 | C46: 46064 | D46: First Issue | G46: EF | H46: NPB | I46: CW
B47: Revision | C47: Date | D47: Description | G47: By | H47: Chk | I47: App
B49: Carrington Field Street | Stockport | Cheshire | SK1 3JN
B50: Tel: 0161 429 4500 | Fax: 0161 476 3095 | Email: admin@sellacontrols.com | Web: www.sellacontrols.com

Sheet 005_AI
A1: TAG | B1: DESCRIPTION | C1: SIGNAL TYPE | D1: CHASSIS &SLOT No | E1: Channel No. | F1: Signal | G1: MODULE | H1: CONNECTION BOARD | I1: CB TERM. | J1: DEVICE LOCATION | K1: DEVICE TAG | L1: WIRE COLOUR | M1: WIRE TYPE | N1: WIRE NUMBER | O1: TERMINAL BLOCK | P1: TERM. No. | Q1: Loop Type | R1: REV.
A2: B10E-PS-OXMON-01 | B2: Oxygen Monitor 01 | C2: 4-20mA | D2: {=_xlfn.LET(_xlpm.filepath,CELL("filename",D2),MID(_xlpm.filepath,FIND("]",_xlpm.filepath)+1,3))} -> 005 | E2: 1 | F2: ="S"&E2&"+" -> S1+ | G2: X-AI 32 02 | H2: X-CB 008 01 | I2: =TEXT(E2,"00")&"a" -> 01a | J2: HUTCH | K2: B10E-PS-OXMON-01 | M2: 3 x 0.5mm² LSZH | Q2: AI2 | R2: 0
F3: ="AI"&E2&"+" -> AI1+ | I3: =TEXT(E2,"00")&"b" -> 01b | L3: White (tri cable) | N3: =D2&"/"&F3 -> 005/AI1+ | O3: X-OXMON | P3: 3
F4: ="AI"&E2&"-" -> AI1- | I4: =TEXT(E2,"00")&"c" -> 01c
F5: 12L+/14 | L5: Brown (tri cable) | N5: 12L+/14 | O5: X-OXMON | P5: 1
F6: 12L-/14 | L6: Green (tri cable) | N6: 12L-/14 | O6: X-OXMON | P6: 4
A7: B10E-PS-OXMON-02 | B7: Oxygen Monitor 02 | C7: 4-20mA | D7: {=_xlfn.LET(_xlpm.filepath,CELL("filename",D7),MID(_xlpm.filepath,FIND("]",_xlpm.filepath)+1,3))} -> 005 | E7: 2 | F7: ="S"&E7&"+" -> S2+ | G7: X-AI 32 02 | H7: X-CB 008 01 | I7: =TEXT(E7,"00")&"a" -> 02a | J7: HUTCH | K7: B10E-PS-OXMON-02 | M7: 3 x 0.5mm² LSZH | Q7: AI2 | R7: 0
F8: ="AI"&E7&"+" -> AI2+ | I8: =TEXT(E7,"00")&"b" -> 02b | L8: White (tri cable) | N8: =D7&"/"&F8 -> 005/AI2+ | O8: X-OXMON | P8: 7
F9: ="AI"&E7&"-" -> AI2- | I9: =TEXT(E7,"00")&"c" -> 02c
F10: 12L+/14 | L10: Brown (tri cable) | N10: 12L+/14 | O10: X-OXMON | P10: 5
F11: 12L-/14 | L11: Green (tri cable) | N11: 12L-/14 | O11: X-OXMON | P11: 8
A12: B10E-PS-OXMON-03 | B12: Oxygen Monitor 03 | C12: 4-20mA | D12: {=_xlfn.LET(_xlpm.filepath,CELL("filename",D12),MID(_xlpm.filepath,FIND("]",_xlpm.filepath)+1,3))} -> 005 | E12: 3 | F12: ="S"&E12&"+" -> S3+ | G12: X-AI 32 02 | H12: X-CB 008 01 | I12: =TEXT(E12,"00")&"a" -> 03a | J12: HUTCH | K12: B10E-PS-OXMON-03 | M12: 3 x 0.5mm² LSZH | Q12: AI2 | R12: 0/1
F13: ="AI"&E12&"+" -> AI3+ | I13: =TEXT(E12,"00")&"b" -> 03b | L13: White (tri cable) | N13: =D12&"/"&F13 -> 005/AI3+ | O13: X-OXMON | P13: 11
F14: ="AI"&E12&"-" -> AI3- | I14: =TEXT(E12,"00")&"c" -> 03c
F15: 12L+/15 | L15: Brown (tri cable) | N15: 12L+/15 | O15: X-OXMON | P15: 9
F16: 12L-/15 | L16: Green (tri cable) | N16: 12L-/15 | O16: X-OXMON | P16: 12
A17: B10E-PS-OXMON-04 | B17: Oxygen Monitor 04 | C17: 4-20mA | D17: {=_xlfn.LET(_xlpm.filepath,CELL("filename",D17),MID(_xlpm.filepath,FIND("]",_xlpm.filepath)+1,3))} -> 005 | E17: 4 | F17: ="S"&E17&"+" -> S4+ | G17: X-AI 32 02 | H17: X-CB 008 01 | I17: =TEXT(E17,"00")&"a" -> 04a | J17: HUTCH | K17: B10E-PS-OXMON-04 | M17: 3 x 0.5mm² LSZH | Q17: AI2 | R17: 0/1
F18: ="AI"&E17&"+" -> AI4+ | I18: =TEXT(E17,"00")&"b" -> 04b | L18: White (tri cable) | N18: =D17&"/"&F18 -> 005/AI4+ | O18: X-OXMON | P18: 15
F19: ="AI"&E17&"-" -> AI4- | I19: =TEXT(E17,"00")&"c" -> 04c
F20: 12L+/15 | L20: Brown (tri cable) | N20: 12L+/15 | O20: X-OXMON | P20: 13
F21: 12L-/15 | L21: Green (tri cable) | N21: 12L-/15 | O21: X-OXMON | P21: 16
A22: ="SPAI-"&D22&"/"&E22 -> SPAI-005/5 | B22: Wired Spare Input | C22: 4-20mA | D22: {=_xlfn.LET(_xlpm.filepath,CELL("filename",D22),MID(_xlpm.filepath,FIND("]",_xlpm.filepath)+1,3))} -> 005 | E22: 5 | F22: ="S"&E22&"+" -> S5+ | G22: X-AI 32 02 | H22: X-CB 008 01 | I22: =TEXT(E22,"00")&"a" -> 05a | L22: Brown (tri cable) | M22: 3 x 0.5mm² LSZH | N22: =D22&"/"&F22 -> 005/S5+ | O22: X-SPAI | P22: 1 | Q22: AI1 | R22: 0/1 | T22: Removed
F23: ="AI"&E22&"+" -> AI5+ | I23: =TEXT(E22,"00")&"b" -> 05b | L23: White (tri cable) | N23: =D22&"/"&F23 -> 005/AI5+ | O23: X-SPAI | P23: 2
F24: ="AI"&E22&"-" -> AI5- | I24: =TEXT(E22,"00")&"c" -> 05c | L24: Green (tri cable) | N24: =D22&"/"&F24 -> 005/AI5- | O24: X-SPAI | P24: 3
A25: ="SPAI-"&D25&"/"&E25 -> SPAI-005/6 | B25: Wired Spare Input | C25: 4-20mA | D25: {=_xlfn.LET(_xlpm.filepath,CELL("filename",D25),MID(_xlpm.filepath,FIND("]",_xlpm.filepath)+1,3))} -> 005 | E25: 6 | F25: ="S"&E25&"+" -> S6+ | G25: X-AI 32 02 | H25: X-CB 008 01 | I25: =TEXT(E25,"00")&"a" -> 06a | L25: Brown (tri cable) | M25: 3 x 0.5mm² LSZH | N25: =D25&"/"&F25 -> 005/S6+ | O25: X-SPAI | P25: 4 | Q25: AI1 | R25: 0/1 | T25: Removed
F26: ="AI"&E25&"+" -> AI6+ | I26: =TEXT(E25,"00")&"b" -> 06b | L26: White (tri cable) | N26: =D25&"/"&F26 -> 005/AI6+ | O26: X-SPAI | P26: 5
F27: ="AI"&E25&"-" -> AI6- | I27: =TEXT(E25,"00")&"c" -> 06c | L27: Green (tri cable) | N27: =D25&"/"&F27 -> 005/AI6- | O27: X-SPAI | P27: 6
A28: B10E-PS-IT-01 | B28: Current Transmitter L1 (E. Source) | C28: 4-20mA | D28: {=_xlfn.LET(_xlpm.filepath,CELL("filename",D28),MID(_xlpm.filepath,FIND("]",_xlpm.filepath)+1,3))} -> 005 | E28: 7 | F28: ="S"&E28&"+" -> S7+ | G28: X-AI 32 02 | H28: X-CB 008 01 | I28: =TEXT(E28,"00")&"a" -> 07a | J28: ELECTRON SOURCE | K28: B10E-PS-IT-01 | L28: Brown (tri cable) | M28: 3 x 0.5mm² LSZH | N28: =D28&"/"&F28 -> 005/S7+ | O28: X-INTF07 | P28: 21 | Q28: AI1 | R28: 0
F29: ="AI"&E28&"+" -> AI7+ | I29: =TEXT(E28,"00")&"b" -> 07b | L29: White (tri cable) | N29: =D28&"/"&F29 -> 005/AI7+ | O29: X-INTF07 | P29: 22
F30: ="AI"&E28&"-" -> AI7- | I30: =TEXT(E28,"00")&"c" -> 07c | L30: Green (tri cable) | N30: =D28&"/"&F30 -> 005/AI7- | O30: X-INTF07 | P30: 23
A31: B10E-PS-IT-02 | B31: Current Transmitter L2 (E. Source) | C31: 4-20mA | D31: {=_xlfn.LET(_xlpm.filepath,CELL("filename",D31),MID(_xlpm.filepath,FIND("]",_xlpm.filepath)+1,3))} -> 005 | E31: 8 | F31: ="S"&E31&"+" -> S8+ | G31: X-AI 32 02 | H31: X-CB 008 01 | I31: =TEXT(E31,"00")&"a" -> 08a | J31: ELECTRON SOURCE | K31: B10E-PS-IT-02 | L31: Brown (tri cable) | M31: 3 x 0.5mm² LSZH | N31: =D31&"/"&F31 -> 005/S8+ | O31: X-INTF07 | P31: 24 | Q31: AI1 | R31: 0
F32: ="AI"&E31&"+" -> AI8+ | I32: =TEXT(E31,"00")&"b" -> 08b | L32: White (tri cable) | N32: =D31&"/"&F32 -> 005/AI8+ | O32: X-INTF07 | P32: 25
F33: ="AI"&E31&"-" -> AI8- | I33: =TEXT(E31,"00")&"c" -> 08c | L33: Green (tri cable) | N33: =D31&"/"&F33 -> 005/AI8- | O33: X-INTF07 | P33: 26
A34: B10E-PS-IT-03 | B34: Current Transmitter L3 (E. Source) | C34: 4-20mA | D34: {=_xlfn.LET(_xlpm.filepath,CELL("filename",D34),MID(_xlpm.filepath,FIND("]",_xlpm.filepath)+1,3))} -> 005 | E34: 9 | F34: ="S"&E34&"+" -> S9+ | G34: X-AI 32 02 | H34: X-CB 008 01 | I34: =TEXT(E34,"00")&"a" -> 09a | J34: ELECTRON SOURCE | K34: B10E-PS-IT-03 | L34: Brown (tri cable) | M34: 3 x 0.5mm² LSZH | N34: =D34&"/"&F34 -> 005/S9+ | O34: X-INTF07 | P34: 27 | Q34: AI1 | R34: 0
F35: ="AI"&E34&"+" -> AI9+ | I35: =TEXT(E34,"00")&"b" -> 09b | L35: White (tri cable) | N35: =D34&"/"&F35 -> 005/AI9+ | O35: X-INTF07 | P35: 28
F36: ="AI"&E34&"-" -> AI9- | I36: =TEXT(E34,"00")&"c" -> 09c | L36: Green (tri cable) | N36: =D34&"/"&F36 -> 005/AI9- | O36: X-INTF07 | P36: 29
A37: B10E-PS-VT-01 | B37: Voltage Transmitter L1 (E. Source) | C37: 4-20mA | D37: {=_xlfn.LET(_xlpm.filepath,CELL("filename",D37),MID(_xlpm.filepath,FIND("]",_xlpm.filepath)+1,3))} -> 005 | E37: 10 | F37: ="S"&E37&"+" -> S10+ | G37: X-AI 32 02 | H37: X-CB 008 01 | I37: =TEXT(E37,"00")&"a" -> 10a | J37: ELECTRON SOURCE | K37: B10E-PS-VT-01 | L37: Brown (tri cable) | M37: 3 x 0.5mm² LSZH | N37: =D37&"/"&F37 -> 005/S10+ | O37: X-INTF07 | P37: 30 | Q37: AI1 | R37: 0/2 | T37: Rewire
F38: ="AI"&E37&"+" -> AI10+ | I38: 10b | L38: White (tri cable) | N38: =D37&"/"&F38 -> 005/AI10+ | O38: X-INTF07 | P38: 31
F39: ="AI"&E37&"-" -> AI10- | I39: 10c | L39: Green (tri cable) | N39: =D37&"/"&F39 -> 005/AI10- | O39: X-INTF07 | P39: 32
A40: B10E-PS-VT-02 | B40: Voltage Transmitter L2 (E. Source) | C40: 4-20mA | D40: {=_xlfn.LET(_xlpm.filepath,CELL("filename",D40),MID(_xlpm.filepath,FIND("]",_xlpm.filepath)+1,3))} -> 005 | E40: 11 | F40: ="S"&E40&"+" -> S11+ | G40: X-AI 32 02 | H40: X-CB 008 01 | I40: =TEXT(E40,"00")&"a" -> 11a | J40: ELECTRON SOURCE | K40: B10E-PS-VT-02 | L40: Brown (tri cable) | M40: 3 x 0.5mm² LSZH | N40: =D40&"/"&F40 -> 005/S11+ | O40: X-INTF07 | P40: 33 | Q40: AI1 | R40: 0/2 | T40: Rewire
...

Sheet 007_DI
A1: TAG | B1: DESCRIPTION | C1: SIGNAL TYPE | D1: CHASSIS &SLOT No | E1: Channel. No. | F1: Signal | G1: MODULE | H1: CONNECTION BOARD | I1: CB TERM. | J1: DEVICE LOCATION | K1: DEVICE TAG | L1: WIRE COLOUR | M1: WIRE TYPE | N1: WIRE NUMBER | O1: TERMINAL BLOCK | P1: TERM. No. | Q1: Loop Type | R1: REV.
A2: B10E-PS-FNFLT-01 | B2: Himax Fan Fault | C2: 24Vdc | D2: {=_xlfn.LET(_xlpm.filepath,CELL("filename",D2),MID(_xlpm.filepath,FIND("]",_xlpm.filepath)+1,3))} -> 007 | E2: 1 | F2: ="S"&E2&"+" -> S1+ | G2: X-DI 32 05 | H2: X-CB 005 01 | I2: =E2&"a" -> 1a | J2: LOGIC SOLVER | K2: B10E-PS-FAN-01 | L2: Red | M2: 0.5mm² H05Z-K | N2: =D2&"/"&F2 -> 007/S1+ | O2: FAN-0 | P2: 8 | Q2: DI2 | R2: 0
F3: ="DI"&E2&"+" -> DI1+ | I3: =E2&"b" -> 1b | L3: Grey | M3: 0.5mm² H05Z-K | N3: =D2&"/"&F3 -> 007/DI1+ | O3: FAN-0 | P3: 9
A4: B10E-PS-IOC-01:SYSTEMP | B4: Rack Internal Temperature Alarm | C4: 24Vdc | D4: {=_xlfn.LET(_xlpm.filepath,CELL("filename",D4),MID(_xlpm.filepath,FIND("]",_xlpm.filepath)+1,3))} -> 007 | E4: 2 | F4: ="S"&E4&"+" -> S2+ | G4: =G2 -> X-DI 32 05 | H4: =H2 -> X-CB 005 01 | I4: =E4&"a" -> 2a | J4: LOGIC SOLVER | K4: B10E-PS-STAT-1 | L4: Red | M4: 0.5mm² H05Z-K | N4: =D4&"/"&F4 -> 007/S2+ | O4: STAT-1 | P4: 3 | Q4: DI2 | R4: 0
F5: ="DI"&E4&"+" -> DI2+ | I5: =E4&"b" -> 2b | L5: Grey | M5: 0.5mm² H05Z-K | N5: =D4&"/"&F5 -> 007/DI2+ | O5: STAT-1 | P5: 5
A6: B10E-PS-PSU-01:A1:FAULT | B6: 24VDC PSU A1 Fault | C6: 24Vdc | D6: {=_xlfn.LET(_xlpm.filepath,CELL("filename",D6),MID(_xlpm.filepath,FIND("]",_xlpm.filepath)+1,3))} -> 007 | E6: 3 | F6: ="S"&E6&"+" -> S3+ | G6: =G4 -> X-DI 32 05 | H6: =H2 -> X-CB 005 01 | I6: =E6&"a" -> 3a | J6: LOGIC SOLVER | K6: B10E-PS-PSU-01:A1 | L6: Red | M6: 0.5mm² H05Z-K | N6: =D6&"/"&F6 -> 007/S3+ | O6: PSU-A1 | P6: 13 | Q6: DI2 | R6: 0
F7: ="DI"&E6&"+" -> DI3+ | I7: =E6&"b" -> 3b | L7: Grey | M7: 0.5mm² H05Z-K | N7: =D6&"/"&F7 -> 007/DI3+ | O7: PSU-A1 | P7: 14
A8: B10E-PS-PSU-01:A2:FAULT | B8: 24VDC PSU A2 Fault | C8: 24Vdc | D8: {=_xlfn.LET(_xlpm.filepath,CELL("filename",D8),MID(_xlpm.filepath,FIND("]",_xlpm.filepath)+1,3))} -> 007 | E8: 4 | F8: ="S"&E8&"+" -> S4+ | G8: =G6 -> X-DI 32 05 | H8: =H6 -> X-CB 005 01 | I8: =E8&"a" -> 4a | J8: LOGIC SOLVER | K8: B10E-PS-PSU-01:A2 | L8: Red | M8: 0.5mm² H05Z-K | N8: =D8&"/"&F8 -> 007/S4+ | O8: PSU-A2 | P8: 13 | Q8: DI2 | R8: 0
F9: ="DI"&E8&"+" -> DI4+ | I9: =E8&"b" -> 4b | L9: Grey | M9: 0.5mm² H05Z-K | N9: =D8&"/"&F9 -> 007/DI4+ | O9: PSU-A2 | P9: 14
A10: B10E-PS-PSU-01:A3:FAULT | B10: 24VDC PSU A3 Fault | C10: 24Vdc | D10: {=_xlfn.LET(_xlpm.filepath,CELL("filename",D10),MID(_xlpm.filepath,FIND("]",_xlpm.filepath)+1,3))} -> 007 | E10: 5 | F10: ="S"&E10&"+" -> S5+ | G10: =G8 -> X-DI 32 05 | H10: =H6 -> X-CB 005 01 | I10: =E10&"a" -> 5a | J10: LOGIC SOLVER | K10: B10E-PS-PSU-01:B1 | L10: Red | M10: 0.5mm² H05Z-K | N10: =D10&"/"&F10 -> 007/S5+ | O10: PSU-A3 | P10: 13 | Q10: DI2 | R10: 0/1 | T10: Add
F11: ="DI"&E10&"+" -> DI5+ | I11: =E10&"b" -> 5b | L11: Grey | M11: 0.5mm² H05Z-K | N11: =D10&"/"&F11 -> 007/DI5+ | O11: PSU-A3 | P11: 14
A12: B10E-PS-PSU-01:B1:FAULT | B12: 24VDC PSU B1 Fault | C12: 24Vdc | D12: {=_xlfn.LET(_xlpm.filepath,CELL("filename",D12),MID(_xlpm.filepath,FIND("]",_xlpm.filepath)+1,3))} -> 007 | E12: 6 | F12: ="S"&E12&"+" -> S6+ | G12: =G10 -> X-DI 32 05 | H12: =H10 -> X-CB 005 01 | I12: =E12&"a" -> 6a | J12: LOGIC SOLVER | K12: B10E-PS-PSU-01:B2 | L12: Red | M12: 0.5mm² H05Z-K | N12: =D12&"/"&F12 -> 007/S6+ | O12: PSU-B1 | P12: 13 | Q12: DI2 | R12: 0/1 | T12: Moved
F13: ="DI"&E12&"+" -> DI6+ | I13: =E12&"b" -> 6b | L13: Grey | M13: 0.5mm² H05Z-K | N13: =D12&"/"&F13 -> 007/DI6+ | O13: PSU-B1 | P13: 14
A14: B10E-PS-PSU-01:B2:FAULT | B14: 24VDC PSU B2 Fault | C14: 24Vdc | D14: {=_xlfn.LET(_xlpm.filepath,CELL("filename",D14),MID(_xlpm.filepath,FIND("]",_xlpm.filepath)+1,3))} -> 007 | E14: 7 | F14: ="S"&E14&"+" -> S7+ | G14: =G12 -> X-DI 32 05 | H14: =H10 -> X-CB 005 01 | I14: =E14&"a" -> 7a | J14: LOGIC SOLVER | K14: B10E-PS-SWITCH-01 | L14: Red | M14: 0.5mm² H05Z-K | N14: =D14&"/"&F14 -> 007/S7+ | O14: PSU-B2 | P14: 13 | Q14: DI2 | R14: 0/1 | T14: Moved
F15: ="DI"&E14&"+" -> DI7+ | I15: =E14&"b" -> 7b | L15: Grey | M15: 0.5mm² H05Z-K | N15: =D14&"/"&F15 -> 007/DI7+ | O15: PSU-B2 | P15: 14
A16: B10E-PS-PSU-01:B3FAULT | B16: 24VDC PSU B3 Fault | C16: 24Vdc | D16: {=_xlfn.LET(_xlpm.filepath,CELL("filename",D16),MID(_xlpm.filepath,FIND("]",_xlpm.filepath)+1,3))} -> 007 | E16: 8 | F16: ="S"&E16&"+" -> S8+ | G16: =G14 -> X-DI 32 05 | H16: =H14 -> X-CB 005 01 | I16: =E16&"a" -> 8a | J16: LOGIC SOLVER | K16: B10E-PS-WLT-01 | L16: Red | M16: 0.5mm² H05Z-K | N16: =D16&"/"&F16 -> 007/S8+ | O16: PSU-B3 | P16: 13 | Q16: DI2 | R16: 0/1 | T16: Add
F17: ="DI"&E16&"+" -> DI8+ | I17: =E16&"b" -> 8b | L17: Grey | M17: 0.5mm² H05Z-K | N17: =D16&"/"&F17 -> 007/DI8+ | O17: PSU-B3 | P17: 14
A18: B10E-PS-SWFLT-01 | B18: Network Switch Fault | C18: 24Vdc | D18: {=_xlfn.LET(_xlpm.filepath,CELL("filename",D18),MID(_xlpm.filepath,FIND("]",_xlpm.filepath)+1,3))} -> 007 | E18: 9 | F18: ="S"&E18&"+" -> S9+ | G18: =G16 -> X-DI 32 05 | H18: =H14 -> X-CB 005 01 | I18: =E18&"a" -> 9a | J18: LOGIC SOLVER | K18: B10E-PS-SWITCH-01 | L18: Red | M18: 0.5mm² H05Z-K | N18: =D18&"/"&F18 -> 007/S9+ | O18: SWITCH1 | P18: FAULT1 | Q18: DI2 | R18: 0/1 | T18: Moved
F19: ="DI"&E18&"+" -> DI9+ | I19: =E18&"b" -> 9b | L19: Grey | M19: 0.5mm² H05Z-K | N19: =D18&"/"&F19 -> 007/DI9+ | O19: SWITCH1 | P19: FAULT2
A20: B10E-PS-WLT-01 | B20: White Lights Enable (Relay Feedback) | C20: 24Vdc | D20: {=_xlfn.LET(_xlpm.filepath,CELL("filename",D20),MID(_xlpm.filepath,FIND("]",_xlpm.filepath)+1,3))} -> 007 | E20: 10 | F20: ="S"&E20&"+" -> S10+ | G20: =G18 -> X-DI 32 05 | H20: =H18 -> X-CB 005 01 | I20: =E20&"a" -> 10a | J20: LOGIC SOLVER | K20: B10E-PS-WLT-01 | L20: Red | M20: 0.5mm² H05Z-K | N20: =D20&"/"&F20 -> 007/S10+ | O20: CON-1 | P20: 21 | Q20: DI2 | R20: 0/1 | T20: Moved
F21: ="DI"&E20&"+" -> DI10+ | I21: =E20&"b" -> 10b | L21: Grey | M21: 0.5mm² H05Z-K | N21: =D20&"/"&F21 -> 007/DI10+ | O21: CON-1 | P21: 22
A22: B10E-PS-IOC-01:BOB:RESET | B22: SIS Control Room Reset - CH1 - Beam Off Buttons | C22: 24Vdc | D22: {=_xlfn.LET(_xlpm.filepath,CELL("filename",D22),MID(_xlpm.filepath,FIND("]",_xlpm.filepath)+1,3))} -> 007 | E22: 11 | F22: ="S"&E22&"+" -> S11+ | G22: =G20 -> X-DI 32 05 | H22: =H18 -> X-CB 005 01 | I22: =E22&"a" -> 11a | J22: CCR | K22: B10E-PS-INTF-08 | L22: Red | M22: 0.5mm² H05Z-K | N22: =D22&"/"&F22 -> 007/S11+ | O22: X-INTF08 | P22: 1 | Q22: DI1 | R22: 0
F23: ="DI"&E22&"+" -> DI11+ | I23: =E22&"b" -> 11b | L23: Grey | M23: 0.5mm² H05Z-K | N23: =D22&"/"&F23 -> 007/DI11+ | O23: X-INTF08 | P23: 2
A24: B10E-PS-IOC-01:SYS:RESET | B24: SIS Control Room Reset - CH2 - System | C24: 24Vdc | D24: {=_xlfn.LET(_xlpm.filepath,CELL("filename",D24),MID(_xlpm.filepath,FIND("]",_xlpm.filepath)+1,3))} -> 007 | E24: 12 | F24: ="S"&E24&"+" -> S12+ | G24: =G22 -> X-DI 32 05 | H24: =H22 -> X-CB 005 01 | I24: =E24&"a" -> 12a | J24: CCR | K24: B10E-PS-INTF-08 | L24: Red | M24: 0.5mm² H05Z-K | N24: =D24&"/"&F24 -> 007/S12+ | O24: X-INTF08 | P24: 3 | Q24: DI1 | R24: 0
F25: ="DI"&E24&"+" -> DI12+ | I25: =E24&"b" -> 12b | L25: Grey | M25: 0.5mm² H05Z-K | N25: =D24&"/"&F25 -> 007/DI12+ | O25: X-INTF08 | P25: 4
A26: B10E-PS-IOC-01:RDMN:RESET | B26: SIS Control Room Reset - CH3 - RadMon | C26: 24Vdc | D26: {=_xlfn.LET(_xlpm.filepath,CELL("filename",D26),MID(_xlpm.filepath,FIND("]",_xlpm.filepath)+1,3))} -> 007 | E26: 13 | F26: ="S"&E26&"+" -> S13+ | G26: =G24 -> X-DI 32 05 | H26: =H22 -> X-CB 005 01 | I26: =E26&"a" -> 13a | J26: CCR | K26: B10E-PS-INTF-08 | L26: Red | M26: 0.5mm² H05Z-K | N26: =D26&"/"&F26 -> 007/S13+ | O26: X-INTF08 | P26: 5 | Q26: DI1 | R26: 0
F27: ="DI"&E26&"+" -> DI13+ | I27: =E26&"b" -> 13b | L27: Grey | M27: 0.5mm² H05Z-K | N27: =D26&"/"&F27 -> 007/DI13+ | O27: X-INTF08 | P27: 6
A28: B10E-PS-IOC-01:GAS:RESET | B28: SIS Control Room Reset - CH4 - Gas / O2 | C28: 24Vdc | D28: {=_xlfn.LET(_xlpm.filepath,CELL("filename",D28),MID(_xlpm.filepath,FIND("]",_xlpm.filepath)+1,3))} -> 007 | E28: 14 | F28: ="S"&E28&"+" -> S14+ | G28: =G26 -> X-DI 32 05 | H28: =H26 -> X-CB 005 01 | I28: =E28&"a" -> 14a | J28: CCR | K28: B10E-PS-INTF-08 | L28: Red | M28: 0.5mm² H05Z-K | N28: =D28&"/"&F28 -> 007/S14+ | O28: X-INTF08 | P28: 7 | Q28: DI1 | R28: 0
F29: ="DI"&E28&"+" -> DI14+ | I29: =E28&"b" -> 14b | L29: Grey | M29: 0.5mm² H05Z-K | N29: =D28&"/"&F29 -> 007/DI14+ | O29: X-INTF08 | P29: 8
A30: B10E-PS-KEY-03 | B30: Beamline Enable Key - Rack (Electron Source Enable/Disable) | C30: 24Vdc | D30: {=_xlfn.LET(_xlpm.filepath,CELL("filename",D30),MID(_xlpm.filepath,FIND("]",_xlpm.filepath)+1,3))} -> 007 | E30: 15 | F30: ="S"&E30&"+" -> S15+ | G30: =G28 -> X-DI 32 05 | H30: =H26 -> X-CB 005 01 | I30: =E30&"a" -> 15a | J30: LOCAL CONTROL ROOM | K30: B10E-PS-KEY-03 | L30: Red | M30: 0.5mm² H05Z-K | N30: =D30&"/"&F30 -> 007/S15+ | O30: X-KEY | P30: 1 | Q30: DI1 | R30: 0
F31: ="DI"&E30&"+" -> DI15+ | I31: =E30&"b" -> 15b | L31: Grey | M31: 0.5mm² H05Z-K | N31: =D30&"/"&F31 -> 007/DI15+ | O31: X-KEY | P31: 2
A32: B10E-PS-KEY-02 | B32: Hutch Enable Key (Interlocks Chicane Doors) | C32: 24Vdc | D32: {=_xlfn.LET(_xlpm.filepath,CELL("filename",D32),MID(_xlpm.filepath,FIND("]",_xlpm.filepath)+1,3))} -> 007 | E32: 16 | F32: ="S"&E32&"+" -> S16+ | G32: =G30 -> X-DI 32 05 | H32: =H30 -> X-CB 005 01 | I32: =E32&"a" -> 16a | J32: ZCP | K32: B10E-PS-PKP-01 | L32: Red | M32: 0.5mm² H05Z-K | N32: =D32&"/"&F32 -> 007/S16+ | O32: X-ZCP | P32: 7 | Q32: DI1 | R32: 0
F33: ="DI"&E32&"+" -> DI16+ | I33: =E32&"b" -> 16b | L33: Grey | M33: 0.5mm² H05Z-K | N33: =D32&"/"&F33 -> 007/DI16+ | O33: X-ZCP | P33: 8
A34: B10E-PS-KEY-01 | B34: Beamline Enable Key - ZCP (Electron Source Enable/Disable) | C34: 24Vdc | D34: {=_xlfn.LET(_xlpm.filepath,CELL("filename",D34),MID(_xlpm.filepath,FIND("]",_xlpm.filepath)+1,3))} -> 007 | E34: 17 | F34: ="S"&E34&"+" -> S17+ | G34: =G32 -> X-DI 32 05 | H34: =H30 -> X-CB 005 01 | I34: =E34&"a" -> 17a | J34: ZCP | K34: B10E-PS-PKPE-01 | L34: Red | M34: 0.5mm² H05Z-K | N34: =D34&"/"&F34 -> 007/S17+ | O34: X-ZCP | P34: 3 | Q34: DI1 | R34: 0
F35: ="DI"&E34&"+" -> DI17+ | I35: =E34&"b" -> 17b | L35: Grey | M35: 0.5mm² H05Z-K | N35: =D34&"/"&F35 -> 007/DI17+ | O35: X-ZCP | P35: 4
A36: B10E-PS-SCR-01 | B36: Search Card Reader | C36: 24Vdc | D36: {=_xlfn.LET(_xlpm.filepath,CELL("filename",D36),MID(_xlpm.filepath,FIND("]",_xlpm.filepath)+1,3))} -> 007 | E36: 18 | F36: ="S"&E36&"+" -> S18+ | G36: =G34 -> X-DI 32 05 | H36: =H34 -> X-CB 005 01 | I36: =E36&"a" -> 18a | J36: ZCP | K36: B10E-PS-SCR-01 | L36: Red | M36: 0.5mm² H05Z-K | N36: =D36&"/"&F36 -> 007/S18+ | O36: X-ZCP | P36: 31 | Q36: DI1 | R36: 0
F37: ="DI"&E36&"+" -> DI18+ | I37: =E36&"b" -> 18b | L37: Grey | M37: 0.5mm² H05Z-K | N37: =D36&"/"&F37 -> 007/DI18+ | O37: X-ZCP | P37: 32
A38: B10E-PS-ASBF-01 | B38: Area Search Button Final | C38: 24Vdc | D38: {=_xlfn.LET(_xlpm.filepath,CELL("filename",D38),MID(_xlpm.filepath,FIND("]",_xlpm.filepath)+1,3))} -> 007 | E38: 19 | F38: ="S"&E38&"+" -> S19+ | G38: =G36 -> X-DI 32 05 | H38: =H34 -> X-CB 005 01 | I38: =E38&"a" -> 19a | J38: ZCP | K38: B10E-PS-ASBF-01 | L38: Red | M38: 0.5mm² H05Z-K | N38: =D38&"/"&F38 -> 007/S19+ | O38: X-ZCP | P38: 9 | Q38: DI1 | R38: 0
F39: ="DI"&E38&"+" -> DI19+ | I39: =E38&"b" -> 19b | L39: Grey | M39: 0.5mm² H05Z-K | N39: =D38&"/"&F39 -> 007/DI19+ | O39: X-ZCP | P39: 10
A40: B10E-PS-OR-01 | B40: Open / Reset Pushbutton | C40: 24Vdc | D40: {=_xlfn.LET(_xlpm.filepath,CELL("filename",D40),MID(_xlpm.filepath,FIND("]",_xlpm.filepath)+1,3))} -> 007 | E40: 20 | F40: ="S"&E40&"+" -> S20+ | G40: =G38 -> X-DI 32 05 | H40: =H38 -> X-CB 005 01 | I40: =E40&"a" -> 20a | J40: ZCP | K40: B10E-PS-OR-01 | L40: Red | M40: 0.5mm² H05Z-K | N40: =D40&"/"&F40 -> 007/S20+ | O40: X-ZCP | P40: 13 | Q40: DI1 | R40: 0
...

Sheet 008_DI
A1: TAG | B1: DESCRIPTION | C1: SIGNAL TYPE | D1: CHASSIS &SLOT No | E1: Channel. No. | F1: Signal | G1: MODULE | H1: CONNECTION BOARD | I1: CB TERM. | J1: DEVICE LOCATION | K1: DEVICE TAG | L1: WIRE COLOUR | M1: WIRE TYPE | N1: WIRE NUMBER | O1: TERMINAL BLOCK | P1: TERM. No. | Q1: Loop Type | R1: REV.
A2: B10E-PS-GADC-01 | B2: General Access Door Closed Position Switch 1 (N/O when Door Open) | C2: 24Vdc | D2: {=_xlfn.LET(_xlpm.filepath,CELL("filename",D2),MID(_xlpm.filepath,FIND("]",_xlpm.filepath)+1,3))} -> 008 | E2: 1 | F2: ="S"&E2&"+" -> S1+ | G2: X-DI 32 05 | H2: X-CB 005 01 | I2: =E2&"a" -> 1a | J2: EXTERNAL | K2: B10E-PS-DS-01 | L2: Red | M2: 0.5mm² H05Z-K | N2: =D2&"/"&F2 -> 008/S1+ | O2: X-DS01 | P2: 3 | Q2: DI1 | R2: 0
F3: ="DI"&E2&"+" -> DI1+ | I3: =E2&"b" -> 1b | L3: Grey | M3: 0.5mm² H05Z-K | N3: =D2&"/"&F3 -> 008/DI1+ | O3: X-DS01 | P3: 4
A4: B10E-PS-GADL-01 | B4: General Access Door Locked Position Switch 1 | C4: 24Vdc | D4: {=_xlfn.LET(_xlpm.filepath,CELL("filename",D4),MID(_xlpm.filepath,FIND("]",_xlpm.filepath)+1,3))} -> 008 | E4: 2 | F4: ="S"&E4&"+" -> S2+ | G4: =G2 -> X-DI 32 05 | H4: =H2 -> X-CB 005 01 | I4: =E4&"a" -> 2a | J4: EXTERNAL | K4: B10E-PS-DS-01 | L4: Red | M4: 0.5mm² H05Z-K | N4: =D4&"/"&F4 -> 008/S2+ | O4: X-DS01 | P4: 5 | Q4: DI1 | R4: 0
F5: ="DI"&E4&"+" -> DI2+ | I5: =E4&"b" -> 2b | L5: Grey | M5: 0.5mm² H05Z-K | N5: =D4&"/"&F5 -> 008/DI2+ | O5: X-DS01 | P5: 6
A6: SPDI-008/3 | B6: Wired Spare Input (Reserved) | C6: 24Vdc | D6: {=_xlfn.LET(_xlpm.filepath,CELL("filename",D6),MID(_xlpm.filepath,FIND("]",_xlpm.filepath)+1,3))} -> 008 | E6: 3 | F6: ="S"&E6&"+" -> S3+ | G6: =G4 -> X-DI 32 05 | H6: =H2 -> X-CB 005 01 | I6: =E6&"a" -> 3a | J6: HUTCH | K6: B10E-PS-DS-03 | L6: Red | M6: 0.5mm² H05Z-K | N6: =D6&"/"&F6 -> 008/S3+ | O6: X-DS03 | P6: 3 | Q6: DI1 | R6: 0
F7: ="DI"&E6&"+" -> DI3+ | I7: =E6&"b" -> 3b | L7: Grey | M7: 0.5mm² H05Z-K | N7: =D6&"/"&F7 -> 008/DI3+ | O7: X-DS03 | P7: 4
A8: B10E-PS-GADC-04 | B8: General Access Gate Closed Position Switch 1 (N/O when Gate Open) | C8: 24Vdc | D8: {=_xlfn.LET(_xlpm.filepath,CELL("filename",D8),MID(_xlpm.filepath,FIND("]",_xlpm.filepath)+1,3))} -> 008 | E8: 4 | F8: ="S"&E8&"+" -> S4+ | G8: =G6 -> X-DI 32 05 | H8: =H6 -> X-CB 005 01 | I8: =E8&"a" -> 4a | J8: EXTERNAL | K8: B10E-PS-DS-04 | L8: Red | M8: 0.5mm² H05Z-K | N8: =D8&"/"&F8 -> 008/S4+ | O8: X-DS04 | P8: 3 | Q8: DI1 | R8: 0
F9: ="DI"&E8&"+" -> DI4+ | I9: =E8&"b" -> 4b | L9: Grey | M9: 0.5mm² H05Z-K | N9: =D8&"/"&F9 -> 008/DI4+ | O9: X-DS04 | P9: 4
A10: B10E-PS-GADL-04 | B10: General Access Gate Locked Position Switch 1 | C10: 24Vdc | D10: {=_xlfn.LET(_xlpm.filepath,CELL("filename",D10),MID(_xlpm.filepath,FIND("]",_xlpm.filepath)+1,3))} -> 008 | E10: 5 | F10: ="S"&E10&"+" -> S5+ | G10: =G8 -> X-DI 32 05 | H10: =H6 -> X-CB 005 01 | I10: =E10&"a" -> 5a | J10: EXTERNAL | K10: B10E-PS-DS-04 | L10: Red | M10: 0.5mm² H05Z-K | N10: =D10&"/"&F10 -> 008/S5+ | O10: X-DS04 | P10: 5 | Q10: DI1 | R10: 0
F11: ="DI"&E10&"+" -> DI5+ | I11: =E10&"b" -> 5b | L11: Grey | M11: 0.5mm² H05Z-K | N11: =D10&"/"&F11 -> 008/DI5+ | O11: X-DS04 | P11: 6
A12: SPDI-008/6 | B12: Wired Spare Input (Reserved) | C12: 24Vdc | D12: {=_xlfn.LET(_xlpm.filepath,CELL("filename",D12),MID(_xlpm.filepath,FIND("]",_xlpm.filepath)+1,3))} -> 008 | E12: 6 | F12: ="S"&E12&"+" -> S6+ | G12: =G10 -> X-DI 32 05 | H12: =H10 -> X-CB 005 01 | I12: =E12&"a" -> 6a | J12: EXTERNAL | K12: B10E-PS-DS-06 | L12: Red | M12: 0.5mm² H05Z-K | N12: =D12&"/"&F12 -> 008/S6+ | O12: X-DS06 | P12: 3 | Q12: DI2 | R12: 0/1
F13: ="DI"&E12&"+" -> DI6+ | I13: =E12&"b" -> 6b | L13: Grey | M13: 0.5mm² H05Z-K | N13: =D12&"/"&F13 -> 008/DI6+ | O13: X-DS06 | P13: 4
A14: B10E-PS-SADC-01 | B14: Service Access Door Closed Position Switch 1 (N/O when Door Open) | C14: 24Vdc | D14: {=_xlfn.LET(_xlpm.filepath,CELL("filename",D14),MID(_xlpm.filepath,FIND("]",_xlpm.filepath)+1,3))} -> 008 | E14: 7 | F14: ="S"&E14&"+" -> S7+ | G14: =G12 -> X-DI 32 05 | H14: =H10 -> X-CB 005 01 | I14: =E14&"a" -> 7a | J14: EXTERNAL | K14: B10E-PS-DS-07 | L14: Red | M14: 0.5mm² H05Z-K | N14: =D14&"/"&F14 -> 008/S7+ | O14: X-DS07 | P14: 3 | Q14: DI1 | R14: 0
F15: ="DI"&E14&"+" -> DI7+ | I15: =E14&"b" -> 7b | L15: Grey | M15: 0.5mm² H05Z-K | N15: =D14&"/"&F15 -> 008/DI7+ | O15: X-DS07 | P15: 4
A16: B10E-PS-SADL-01 | B16: Service Access Door Locked Position Switch 1 | C16: 24Vdc | D16: {=_xlfn.LET(_xlpm.filepath,CELL("filename",D16),MID(_xlpm.filepath,FIND("]",_xlpm.filepath)+1,3))} -> 008 | E16: 8 | F16: ="S"&E16&"+" -> S8+ | G16: =G14 -> X-DI 32 05 | H16: =H14 -> X-CB 005 01 | I16: =E16&"a" -> 8a | J16: EXTERNAL | K16: B10E-PS-DS-07 | L16: Red | M16: 0.5mm² H05Z-K | N16: =D16&"/"&F16 -> 008/S8+ | O16: X-DS07 | P16: 5 | Q16: DI1 | R16: 0
F17: ="DI"&E16&"+" -> DI8+ | I17: =E16&"b" -> 8b | L17: Grey | M17: 0.5mm² H05Z-K | N17: =D16&"/"&F17 -> 008/DI8+ | O17: X-DS07 | P17: 6
A18: SPDI-008/9 | B18: Wired Spare Input (Reserved) | C18: 24Vdc | D18: {=_xlfn.LET(_xlpm.filepath,CELL("filename",D18),MID(_xlpm.filepath,FIND("]",_xlpm.filepath)+1,3))} -> 008 | E18: 9 | F18: ="S"&E18&"+" -> S9+ | G18: =G16 -> X-DI 32 05 | H18: =H14 -> X-CB 005 01 | I18: =E18&"a" -> 9a | J18: HUTCH | K18: B10E-PS-DS-09 | L18: Red | M18: 0.5mm² H05Z-K | N18: =D18&"/"&F18 -> 008/S9+ | O18: X-DS09 | P18: 3 | Q18: DI2 | R18: 0/1
F19: ="DI"&E18&"+" -> DI9+ | I19: =E18&"b" -> 9b | L19: Grey | M19: 0.5mm² H05Z-K | N19: =D18&"/"&F19 -> 008/DI9+ | O19: X-DS09 | P19: 4
A20: B10E-PS-SADC-04 | B20: Service Access Door Closed Position Switch 4 (N/O when Door Open) | C20: 24Vdc | D20: {=_xlfn.LET(_xlpm.filepath,CELL("filename",D20),MID(_xlpm.filepath,FIND("]",_xlpm.filepath)+1,3))} -> 008 | E20: 10 | F20: ="S"&E20&"+" -> S10+ | G20: =G18 -> X-DI 32 05 | H20: =H18 -> X-CB 005 01 | I20: =E20&"a" -> 10a | J20: HUTCH | K20: B10E-PS-DS-10 | L20: Red | M20: 0.5mm² H05Z-K | N20: =D20&"/"&F20 -> 008/S10+ | O20: X-DS10 | P20: 1 | Q20: DI1 | R20: 0
F21: ="DI"&E20&"+" -> DI10+ | I21: =E20&"b" -> 10b | L21: Grey | M21: 0.5mm² H05Z-K | N21: =D20&"/"&F21 -> 008/DI10+ | O21: X-DS10 | P21: 2
A22: SPDI-008/11 | B22: Wired Spare Input (RESERVED) | C22: 24Vdc | D22: {=_xlfn.LET(_xlpm.filepath,CELL("filename",D22),MID(_xlpm.filepath,FIND("]",_xlpm.filepath)+1,3))} -> 008 | E22: 11 | F22: ="S"&E22&"+" -> S11+ | G22: =G20 -> X-DI 32 05 | H22: =H18 -> X-CB 005 01 | I22: =E22&"a" -> 11a | K22: B10E-PS-DS-10 | L22: Red | M22: 0.5mm² H05Z-K | N22: =D22&"/"&F22 -> 008/S11+ | O22: X-DS10 | P22: 3 | Q22: DI2 | R22: 0/1
F23: ="DI"&E22&"+" -> DI11+ | I23: =E22&"b" -> 11b | L23: Grey | M23: 0.5mm² H05Z-K | N23: =D22&"/"&F23 -> 008/DI11+ | O23: X-DS10 | P23: 4
A24: B10E-PS-KEY-04 | B24: Software Download/Program Enable Keyswitch | C24: 24Vdc | D24: {=_xlfn.LET(_xlpm.filepath,CELL("filename",D24),MID(_xlpm.filepath,FIND("]",_xlpm.filepath)+1,3))} -> 008 | E24: 12 | F24: ="S"&E24&"+" -> S12+ | G24: =G22 -> X-DI 32 05 | H24: =H22 -> X-CB 005 01 | I24: =E24&"a" -> 12a | J24: LOGIC SOLVER | K24: B10E-PS-KEY-04 | L24: Red | M24: 0.5mm² H05Z-K | N24: =D24&"/"&F24 -> 008/S12+ | O24: KS-1 | P24: 13 | Q24: DI2 | R24: 0/1 | T24: Changed
F25: ="DI"&E24&"+" -> DI12+ | I25: =E24&"b" -> 12b | L25: Grey | M25: 0.5mm² H05Z-K | N25: =D24&"/"&F25 -> 008/DI12+ | O25: KS-1 | P25: 23
A26: B10E-PS-BOB-01:A | B26: Beam Off Button 01 | C26: 24Vdc | D26: {=_xlfn.LET(_xlpm.filepath,CELL("filename",D26),MID(_xlpm.filepath,FIND("]",_xlpm.filepath)+1,3))} -> 008 | E26: 13 | F26: ="S"&E26&"+" -> S13+ | G26: =G24 -> X-DI 32 05 | H26: =H22 -> X-CB 005 01 | I26: =E26&"a" -> 13a | J26: ZCP | K26: B10E-PS-BOB-01 | L26: Red | M26: 0.5mm² H05Z-K | N26: =D26&"/"&F26 -> 008/S13+ | O26: X-ZCP | P26: 17 | Q26: DI1 | R26: 0
B27: 5 | F27: ="DI"&E26&"+" -> DI13+ | I27: =E26&"b" -> 13b | L27: Grey | M27: 0.5mm² H05Z-K | N27: =D26&"/"&F27 -> 008/DI13+ | O27: X-ZCP | P27: 18
A28: B10E-PS-BOB-02:A | B28: Beam Off Button 02 | C28: 24Vdc | D28: {=_xlfn.LET(_xlpm.filepath,CELL("filename",D28),MID(_xlpm.filepath,FIND("]",_xlpm.filepath)+1,3))} -> 008 | E28: 14 | F28: ="S"&E28&"+" -> S14+ | G28: =G26 -> X-DI 32 05 | H28: =H26 -> X-CB 005 01 | I28: =E28&"a" -> 14a | J28: HUTCH | K28: B10E-PS-BOB-02 | L28: Red | M28: 0.5mm² H05Z-K | N28: =D28&"/"&F28 -> 008/S14+ | O28: X-BOB | P28: 1 | Q28: DI1 | R28: 0
F29: ="DI"&E28&"+" -> DI14+ | I29: =E28&"b" -> 14b | L29: Grey | M29: 0.5mm² H05Z-K | N29: =D28&"/"&F29 -> 008/DI14+ | O29: X-BOB | P29: 2
A30: B10E-PS-BOB-03:A | B30: Beam Off Button 03 | C30: 24Vdc | D30: {=_xlfn.LET(_xlpm.filepath,CELL("filename",D30),MID(_xlpm.filepath,FIND("]",_xlpm.filepath)+1,3))} -> 008 | E30: 15 | F30: ="S"&E30&"+" -> S15+ | G30: =G28 -> X-DI 32 05 | H30: =H26 -> X-CB 005 01 | I30: =E30&"a" -> 15a | J30: HUTCH | K30: B10E-PS-BOB-03 | L30: Red | M30: 0.5mm² H05Z-K | N30: =D30&"/"&F30 -> 008/S15+ | O30: X-BOB | P30: 5 | Q30: DI1 | R30: 0
F31: ="DI"&E30&"+" -> DI15+ | I31: =E30&"b" -> 15b | L31: Grey | M31: 0.5mm² H05Z-K | N31: =D30&"/"&F31 -> 008/DI15+ | O31: X-BOB | P31: 6
A32: B10E-PS-BOB-04:A | B32: Beam Off Button 04 | C32: 24Vdc | D32: {=_xlfn.LET(_xlpm.filepath,CELL("filename",D32),MID(_xlpm.filepath,FIND("]",_xlpm.filepath)+1,3))} -> 008 | E32: 16 | F32: ="S"&E32&"+" -> S16+ | G32: =G30 -> X-DI 32 05 | H32: =H30 -> X-CB 005 01 | I32: =E32&"a" -> 16a | J32: HUTCH | K32: B10E-PS-BOB-04 | L32: Red | M32: 0.5mm² H05Z-K | N32: =D32&"/"&F32 -> 008/S16+ | O32: X-BOB | P32: 9 | Q32: DI1 | R32: 0
F33: ="DI"&E32&"+" -> DI16+ | I33: =E32&"b" -> 16b | L33: Grey | M33: 0.5mm² H05Z-K | N33: =D32&"/"&F33 -> 008/DI16+ | O33: X-BOB | P33: 10
A34: B10E-PS-BOB-05:A | B34: Beam Off Button 05 | C34: 24Vdc | D34: {=_xlfn.LET(_xlpm.filepath,CELL("filename",D34),MID(_xlpm.filepath,FIND("]",_xlpm.filepath)+1,3))} -> 008 | E34: 17 | F34: ="S"&E34&"+" -> S17+ | G34: =G32 -> X-DI 32 05 | H34: =H30 -> X-CB 005 01 | I34: =E34&"a" -> 17a | J34: HUTCH | K34: B10E-PS-BOB-05 | L34: Red | M34: 0.5mm² H05Z-K | N34: =D34&"/"&F34 -> 008/S17+ | O34: X-BOB | P34: 13 | Q34: DI1 | R34: 0
F35: ="DI"&E34&"+" -> DI17+ | I35: =E34&"b" -> 17b | L35: Grey | M35: 0.5mm² H05Z-K | N35: =D34&"/"&F35 -> 008/DI17+ | O35: X-BOB | P35: 14
A36: B10E-PS-BOB-06:A | B36: Beam Off Button 06 | C36: 24Vdc | D36: {=_xlfn.LET(_xlpm.filepath,CELL("filename",D36),MID(_xlpm.filepath,FIND("]",_xlpm.filepath)+1,3))} -> 008 | E36: 18 | F36: ="S"&E36&"+" -> S18+ | G36: =G34 -> X-DI 32 05 | H36: =H34 -> X-CB 005 01 | I36: =E36&"a" -> 18a | J36: HUTCH | K36: B10E-PS-BOB-06 | L36: Red | M36: 0.5mm² H05Z-K | N36: =D36&"/"&F36 -> 008/S18+ | O36: X-BOB | P36: 17 | Q36: DI1 | R36: 0
F37: ="DI"&E36&"+" -> DI18+ | I37: =E36&"b" -> 18b | L37: Grey | M37: 0.5mm² H05Z-K | N37: =D36&"/"&F37 -> 008/DI18+ | O37: X-BOB | P37: 18
A38: B10E-PS-BOB-07:A | B38: Beam Off Button 07 | C38: 24Vdc | D38: {=_xlfn.LET(_xlpm.filepath,CELL("filename",D38),MID(_xlpm.filepath,FIND("]",_xlpm.filepath)+1,3))} -> 008 | E38: 19 | F38: ="S"&E38&"+" -> S19+ | G38: =G36 -> X-DI 32 05 | H38: =H34 -> X-CB 005 01 | I38: =E38&"a" -> 19a | J38: HUTCH | K38: B10E-PS-BOB-07 | L38: Red | M38: 0.5mm² H05Z-K | N38: =D38&"/"&F38 -> 008/S19+ | O38: X-BOB | P38: 21 | Q38: DI1 | R38: 0
F39: ="DI"&E38&"+" -> DI19+ | I39: =E38&"b" -> 19b | L39: Grey | M39: 0.5mm² H05Z-K | N39: =D38&"/"&F39 -> 008/DI19+ | O39: X-BOB | P39: 22
A40: B10E-PS-BOB-08:A | B40: Beam Off Button 08 | C40: 24Vdc | D40: {=_xlfn.LET(_xlpm.filepath,CELL("filename",D40),MID(_xlpm.filepath,FIND("]",_xlpm.filepath)+1,3))} -> 008 | E40: 20 | F40: ="S"&E40&"+" -> S20+ | G40: =G38 -> X-DI 32 05 | H40: =H38 -> X-CB 005 01 | I40: =E40&"a" -> 20a | J40: HUTCH | K40: B10E-PS-BOB-08 | L40: Red | M40: 0.5mm² H05Z-K | N40: =D40&"/"&F40 -> 008/S20+ | O40: X-BOB | P40: 25 | Q40: DI1 | R40: 0
...

Sheet 009_DI
A1: TAG | B1: DESCRIPTION | C1: SIGNAL TYPE | D1: CHASSIS &SLOT No | E1: Channel. No. | F1: Signal | G1: MODULE | H1: CONNECTION BOARD | I1: CB TERM. | J1: DEVICE LOCATION | K1: DEVICE TAG | L1: WIRE COLOUR | M1: WIRE TYPE | N1: WIRE NUMBER | O1: TERMINAL BLOCK | P1: TERM. No. | Q1: Loop Type | R1: REV.
A2: B10E-PS-GADC-02 | B2: General Access Door Closed Position Switch 2 (N/O when Door Open) | C2: 24Vdc | D2: {=_xlfn.LET(_xlpm.filepath,CELL("filename",D2),MID(_xlpm.filepath,FIND("]",_xlpm.filepath)+1,3))} -> 009 | E2: 1 | F2: ="S"&E2&"+" -> S1+ | G2: X-DI 32 05 | H2: X-CB 005 01 | I2: =E2&"a" -> 1a | J2: EXTERNAL | K2: B10E-PS-DS-02 | L2: Red | M2: 0.5mm² H05Z-K | N2: =D2&"/"&F2 -> 009/S1+ | O2: X-DS02 | P2: 3 | Q2: DI1 | R2: 0
F3: ="DI"&E2&"+" -> DI1+ | I3: =E2&"b" -> 1b | L3: Grey | M3: 0.5mm² H05Z-K | N3: =D2&"/"&F3 -> 009/DI1+ | O3: X-DS02 | P3: 4
A4: B10E-PS-GADL-02 | B4: General Access Door Locked Position Switch 2 | C4: 24Vdc | D4: {=_xlfn.LET(_xlpm.filepath,CELL("filename",D4),MID(_xlpm.filepath,FIND("]",_xlpm.filepath)+1,3))} -> 009 | E4: 2 | F4: ="S"&E4&"+" -> S2+ | G4: =G2 -> X-DI 32 05 | H4: =H2 -> X-CB 005 01 | I4: =E4&"a" -> 2a | J4: EXTERNAL | K4: B10E-PS-DS-02 | L4: Red | M4: 0.5mm² H05Z-K | N4: =D4&"/"&F4 -> 009/S2+ | O4: X-DS02 | P4: 5 | Q4: DI1 | R4: 0
F5: ="DI"&E4&"+" -> DI2+ | I5: =E4&"b" -> 2b | L5: Grey | M5: 0.5mm² H05Z-K | N5: =D4&"/"&F5 -> 009/DI2+ | O5: X-DS02 | P5: 6
A6: SPDI-009/3 | B6: Wired Spare Input | C6: 24Vdc | D6: {=_xlfn.LET(_xlpm.filepath,CELL("filename",D6),MID(_xlpm.filepath,FIND("]",_xlpm.filepath)+1,3))} -> 009 | E6: 3 | F6: ="S"&E6&"+" -> S3+ | G6: =G4 -> X-DI 32 05 | H6: =H2 -> X-CB 005 01 | I6: =E6&"a" -> 3a | L6: Red | M6: 0.5mm² H05Z-K | N6: =D6&"/"&F6 -> 009/S3+ | O6: X-SPDI | P6: 13 | Q6: DI2 | R6: 0/1 | T6: change term
F7: ="DI"&E6&"+" -> DI3+ | I7: =E6&"b" -> 3b | L7: Grey | M7: 0.5mm² H05Z-K | N7: =D6&"/"&F7 -> 009/DI3+ | O7: X-SPDI | P7: 14
A8: B10E-PS-GADC-05 | B8: General Access Gate Closed Position Switch 2 (N/O when Gate Open) | C8: 24Vdc | D8: {=_xlfn.LET(_xlpm.filepath,CELL("filename",D8),MID(_xlpm.filepath,FIND("]",_xlpm.filepath)+1,3))} -> 009 | E8: 4 | F8: ="S"&E8&"+" -> S4+ | G8: =G6 -> X-DI 32 05 | H8: =H6 -> X-CB 005 01 | I8: =E8&"a" -> 4a | J8: EXTERNAL | K8: B10E-PS-DS-05 | L8: Red | M8: 0.5mm² H05Z-K | N8: =D8&"/"&F8 -> 009/S4+ | O8: X-DS05 | P8: 3 | Q8: DI1 | R8: 0
F9: ="DI"&E8&"+" -> DI4+ | I9: =E8&"b" -> 4b | L9: Grey | M9: 0.5mm² H05Z-K | N9: =D8&"/"&F9 -> 009/DI4+ | O9: X-DS05 | P9: 4
A10: B10E-PS-GADL-05 | B10: General Access Gate Locked Position Switch 1 | C10: 24Vdc | D10: {=_xlfn.LET(_xlpm.filepath,CELL("filename",D10),MID(_xlpm.filepath,FIND("]",_xlpm.filepath)+1,3))} -> 009 | E10: 5 | F10: ="S"&E10&"+" -> S5+ | G10: =G8 -> X-DI 32 05 | H10: =H6 -> X-CB 005 01 | I10: =E10&"a" -> 5a | J10: EXTERNAL | K10: B10E-PS-DS-05 | L10: Red | M10: 0.5mm² H05Z-K | N10: =D10&"/"&F10 -> 009/S5+ | O10: X-DS05 | P10: 5 | Q10: DI1 | R10: 0
F11: ="DI"&E10&"+" -> DI5+ | I11: =E10&"b" -> 5b | L11: Grey | M11: 0.5mm² H05Z-K | N11: =D10&"/"&F11 -> 009/DI5+ | O11: X-DS05 | P11: 6
A12: SPDI-009/6 | B12: Wired Spare Input | C12: 24Vdc | D12: {=_xlfn.LET(_xlpm.filepath,CELL("filename",D12),MID(_xlpm.filepath,FIND("]",_xlpm.filepath)+1,3))} -> 009 | E12: 6 | F12: ="S"&E12&"+" -> S6+ | G12: =G10 -> X-DI 32 05 | H12: =H10 -> X-CB 005 01 | I12: =E12&"a" -> 6a | L12: Red | M12: 0.5mm² H05Z-K | N12: =D12&"/"&F12 -> 009/S6+ | O12: X-SPDI | P12: 15 | Q12: DI2 | R12: 0/1 | T12: term change
F13: ="DI"&E12&"+" -> DI6+ | I13: =E12&"b" -> 6b | L13: Grey | M13: 0.5mm² H05Z-K | N13: =D12&"/"&F13 -> 009/DI6+ | O13: X-SPDI | P13: 16
A14: B10E-PS-SADC-02 | B14: Service Access Door Closed Position Switch 2 (N/O when Door Open) | C14: 24Vdc | D14: {=_xlfn.LET(_xlpm.filepath,CELL("filename",D14),MID(_xlpm.filepath,FIND("]",_xlpm.filepath)+1,3))} -> 009 | E14: 7 | F14: ="S"&E14&"+" -> S7+ | G14: =G12 -> X-DI 32 05 | H14: =H10 -> X-CB 005 01 | I14: =E14&"a" -> 7a | J14: EXTERNAL | K14: B10E-PS-DS-08 | L14: Red | M14: 0.5mm² H05Z-K | N14: =D14&"/"&F14 -> 009/S7+ | O14: X-DS08 | P14: 3 | Q14: DI1 | R14: 0
F15: ="DI"&E14&"+" -> DI7+ | I15: =E14&"b" -> 7b | L15: Grey | M15: 0.5mm² H05Z-K | N15: =D14&"/"&F15 -> 009/DI7+ | O15: X-DS08 | P15: 4
A16: B10E-PS-SADL-02 | B16: Service Access Door Locked Position Switch 2 | C16: 24Vdc | D16: {=_xlfn.LET(_xlpm.filepath,CELL("filename",D16),MID(_xlpm.filepath,FIND("]",_xlpm.filepath)+1,3))} -> 009 | E16: 8 | F16: ="S"&E16&"+" -> S8+ | G16: =G14 -> X-DI 32 05 | H16: =H14 -> X-CB 005 01 | I16: =E16&"a" -> 8a | J16: EXTERNAL | K16: B10E-PS-DS-08 | L16: Red | M16: 0.5mm² H05Z-K | N16: =D16&"/"&F16 -> 009/S8+ | O16: X-DS08 | P16: 5 | Q16: DI1 | R16: 0
F17: ="DI"&E16&"+" -> DI8+ | I17: =E16&"b" -> 8b | L17: Grey | M17: 0.5mm² H05Z-K | N17: =D16&"/"&F17 -> 009/DI8+ | O17: X-DS08 | P17: 6
A18: SPDI-009/9 | B18: Wired Spare Input (RESERVED) | C18: 24Vdc | D18: {=_xlfn.LET(_xlpm.filepath,CELL("filename",D18),MID(_xlpm.filepath,FIND("]",_xlpm.filepath)+1,3))} -> 009 | E18: 9 | F18: ="S"&E18&"+" -> S9+ | G18: =G16 -> X-DI 32 05 | H18: =H14 -> X-CB 005 01 | I18: =E18&"a" -> 9a | K18: B10E-PS-DS-09 | L18: Red | M18: 0.5mm² H05Z-K | N18: =D18&"/"&F18 -> 009/S9+ | O18: X-SPDI | P18: 17 | Q18: DI2 | R18: 0/1 | T18: term change
F19: ="DI"&E18&"+" -> DI9+ | I19: =E18&"b" -> 9b | L19: Grey | M19: 0.5mm² H05Z-K | N19: =D18&"/"&F19 -> 009/DI9+ | O19: X-SPDI | P19: 18
A20: B10E-PS-SADC-05 | B20: Service Access Door Closed Position Switch 5 (N/O when Door Open) | C20: 24Vdc | D20: {=_xlfn.LET(_xlpm.filepath,CELL("filename",D20),MID(_xlpm.filepath,FIND("]",_xlpm.filepath)+1,3))} -> 009 | E20: 10 | F20: ="S"&E20&"+" -> S10+ | G20: =G18 -> X-DI 32 05 | H20: =H18 -> X-CB 005 01 | I20: =E20&"a" -> 10a | J20: HUTCH | K20: B10E-PS-DS-11 | L20: Red | M20: 0.5mm² H05Z-K | N20: =D20&"/"&F20 -> 009/S10+ | O20: X-DS11 | P20: 1 | Q20: DI1 | R20: 0
F21: ="DI"&E20&"+" -> DI10+ | I21: =E20&"b" -> 10b | L21: Grey | M21: 0.5mm² H05Z-K | N21: =D20&"/"&F21 -> 009/DI10+ | O21: X-DS11 | P21: 2
A22: SPDI-009/11 | B22: Wired Spare Input (RESERVED) | C22: 24Vdc | D22: {=_xlfn.LET(_xlpm.filepath,CELL("filename",D22),MID(_xlpm.filepath,FIND("]",_xlpm.filepath)+1,3))} -> 009 | E22: 11 | F22: ="S"&E22&"+" -> S11+ | G22: =G20 -> X-DI 32 05 | H22: =H18 -> X-CB 005 01 | I22: =E22&"a" -> 11a | K22: B10E-PS-DS-11 | L22: Red | M22: 0.5mm² H05Z-K | N22: =D22&"/"&F22 -> 009/S11+ | O22: X-DS11 | P22: 3 | Q22: DI2 | R22: 0/1
F23: ="DI"&E22&"+" -> DI11+ | I23: =E22&"b" -> 11b | L23: Grey | M23: 0.5mm² H05Z-K | N23: =D22&"/"&F23 -> 009/DI11+ | O23: X-DS11 | P23: 4
A24: ="SPDI-"&D24&"/"&E24 -> SPDI-009/12 | B24: Wired Spare Input | C24: 24Vdc | D24: {=_xlfn.LET(_xlpm.filepath,CELL("filename",D24),MID(_xlpm.filepath,FIND("]",_xlpm.filepath)+1,3))} -> 009 | E24: 12 | F24: ="S"&E24&"+" -> S12+ | G24: =G22 -> X-DI 32 05 | H24: =H22 -> X-CB 005 01 | I24: =E24&"a" -> 12a | J24: HUTCH | K24: B10E-PS-DS-12 | L24: Red | M24: 0.5mm² H05Z-K | N24: =D24&"/"&F24 -> 009/S12+ | O24: X-SPDI | P24: 19 | Q24: DI2 | R24: 0/1 | T24: Removed
F25: ="DI"&E24&"+" -> DI12+ | I25: =E24&"b" -> 12b | L25: Grey | M25: 0.5mm² H05Z-K | N25: =D24&"/"&F25 -> 009/DI12+ | O25: X-SPDI | P25: 20 | T25: change to spare
A26: B10E-PS-BOB-01:B | B26: Beam Off Button 01 | C26: 24Vdc | D26: {=_xlfn.LET(_xlpm.filepath,CELL("filename",D26),MID(_xlpm.filepath,FIND("]",_xlpm.filepath)+1,3))} -> 009 | E26: 13 | F26: ="S"&E26&"+" -> S13+ | G26: =G24 -> X-DI 32 05 | H26: =H22 -> X-CB 005 01 | I26: =E26&"a" -> 13a | J26: ZCP | K26: B10E-PS-BOB-01 | L26: Red | M26: 0.5mm² H05Z-K | N26: =D26&"/"&F26 -> 009/S13+ | O26: X-ZCP | P26: 19 | Q26: DI1 | R26: 0
F27: ="DI"&E26&"+" -> DI13+ | I27: =E26&"b" -> 13b | L27: Grey | M27: 0.5mm² H05Z-K | N27: =D26&"/"&F27 -> 009/DI13+ | O27: X-ZCP | P27: 20
A28: B10E-PS-BOB-02:B | B28: Beam Off Button 02 | C28: 24Vdc | D28: {=_xlfn.LET(_xlpm.filepath,CELL("filename",D28),MID(_xlpm.filepath,FIND("]",_xlpm.filepath)+1,3))} -> 009 | E28: 14 | F28: ="S"&E28&"+" -> S14+ | G28: =G26 -> X-DI 32 05 | H28: =H26 -> X-CB 005 01 | I28: =E28&"a" -> 14a | J28: HUTCH | K28: B10E-PS-BOB-02 | L28: Red | M28: 0.5mm² H05Z-K | N28: =D28&"/"&F28 -> 009/S14+ | O28: X-BOB | P28: 3 | Q28: DI1 | R28: 0
F29: ="DI"&E28&"+" -> DI14+ | I29: =E28&"b" -> 14b | L29: Grey | M29: 0.5mm² H05Z-K | N29: =D28&"/"&F29 -> 009/DI14+ | O29: X-BOB | P29: 4
A30: B10E-PS-BOB-03:B | B30: Beam Off Button 03 | C30: 24Vdc | D30: {=_xlfn.LET(_xlpm.filepath,CELL("filename",D30),MID(_xlpm.filepath,FIND("]",_xlpm.filepath)+1,3))} -> 009 | E30: 15 | F30: ="S"&E30&"+" -> S15+ | G30: =G28 -> X-DI 32 05 | H30: =H26 -> X-CB 005 01 | I30: =E30&"a" -> 15a | J30: HUTCH | K30: B10E-PS-BOB-03 | L30: Red | M30: 0.5mm² H05Z-K | N30: =D30&"/"&F30 -> 009/S15+ | O30: X-BOB | P30: 7 | Q30: DI1 | R30: 0
F31: ="DI"&E30&"+" -> DI15+ | I31: =E30&"b" -> 15b | L31: Grey | M31: 0.5mm² H05Z-K | N31: =D30&"/"&F31 -> 009/DI15+ | O31: X-BOB | P31: 8
A32: B10E-PS-BOB-04:B | B32: Beam Off Button 04 | C32: 24Vdc | D32: {=_xlfn.LET(_xlpm.filepath,CELL("filename",D32),MID(_xlpm.filepath,FIND("]",_xlpm.filepath)+1,3))} -> 009 | E32: 16 | F32: ="S"&E32&"+" -> S16+ | G32: =G30 -> X-DI 32 05 | H32: =H30 -> X-CB 005 01 | I32: =E32&"a" -> 16a | J32: HUTCH | K32: B10E-PS-BOB-04 | L32: Red | M32: 0.5mm² H05Z-K | N32: =D32&"/"&F32 -> 009/S16+ | O32: X-BOB | P32: 11 | Q32: DI1 | R32: 0
F33: ="DI"&E32&"+" -> DI16+ | I33: =E32&"b" -> 16b | L33: Grey | M33: 0.5mm² H05Z-K | N33: =D32&"/"&F33 -> 009/DI16+ | O33: X-BOB | P33: 12
A34: B10E-PS-BOB-05:B | B34: Beam Off Button 05 | C34: 24Vdc | D34: {=_xlfn.LET(_xlpm.filepath,CELL("filename",D34),MID(_xlpm.filepath,FIND("]",_xlpm.filepath)+1,3))} -> 009 | E34: 17 | F34: ="S"&E34&"+" -> S17+ | G34: =G32 -> X-DI 32 05 | H34: =H30 -> X-CB 005 01 | I34: =E34&"a" -> 17a | J34: HUTCH | K34: B10E-PS-BOB-05 | L34: Red | M34: 0.5mm² H05Z-K | N34: =D34&"/"&F34 -> 009/S17+ | O34: X-BOB | P34: 15 | Q34: DI1 | R34: 0
F35: ="DI"&E34&"+" -> DI17+ | I35: =E34&"b" -> 17b | L35: Grey | M35: 0.5mm² H05Z-K | N35: =D34&"/"&F35 -> 009/DI17+ | O35: X-BOB | P35: 16
A36: B10E-PS-BOB-06:B | B36: Beam Off Button 06 | C36: 24Vdc | D36: {=_xlfn.LET(_xlpm.filepath,CELL("filename",D36),MID(_xlpm.filepath,FIND("]",_xlpm.filepath)+1,3))} -> 009 | E36: 18 | F36: ="S"&E36&"+" -> S18+ | G36: =G34 -> X-DI 32 05 | H36: =H34 -> X-CB 005 01 | I36: =E36&"a" -> 18a | J36: HUTCH | K36: B10E-PS-BOB-06 | L36: Red | M36: 0.5mm² H05Z-K | N36: =D36&"/"&F36 -> 009/S18+ | O36: X-BOB | P36: 19 | Q36: DI1 | R36: 0
F37: ="DI"&E36&"+" -> DI18+ | I37: =E36&"b" -> 18b | L37: Grey | M37: 0.5mm² H05Z-K | N37: =D36&"/"&F37 -> 009/DI18+ | O37: X-BOB | P37: 20
A38: B10E-PS-BOB-07:B | B38: Beam Off Button 07 | C38: 24Vdc | D38: {=_xlfn.LET(_xlpm.filepath,CELL("filename",D38),MID(_xlpm.filepath,FIND("]",_xlpm.filepath)+1,3))} -> 009 | E38: 19 | F38: ="S"&E38&"+" -> S19+ | G38: =G36 -> X-DI 32 05 | H38: =H34 -> X-CB 005 01 | I38: =E38&"a" -> 19a | J38: HUTCH | K38: B10E-PS-BOB-07 | L38: Red | M38: 0.5mm² H05Z-K | N38: =D38&"/"&F38 -> 009/S19+ | O38: X-BOB | P38: 23 | Q38: DI1 | R38: 0
F39: ="DI"&E38&"+" -> DI19+ | I39: =E38&"b" -> 19b | L39: Grey | M39: 0.5mm² H05Z-K | N39: =D38&"/"&F39 -> 009/DI19+ | O39: X-BOB | P39: 24
A40: B10E-PS-BOB-08:B | B40: Beam Off Button 08 | C40: 24Vdc | D40: {=_xlfn.LET(_xlpm.filepath,CELL("filename",D40),MID(_xlpm.filepath,FIND("]",_xlpm.filepath)+1,3))} -> 009 | E40: 20 | F40: ="S"&E40&"+" -> S20+ | G40: =G38 -> X-DI 32 05 | H40: =H38 -> X-CB 005 01 | I40: =E40&"a" -> 20a | J40: HUTCH | K40: B10E-PS-BOB-08 | L40: Red | M40: 0.5mm² H05Z-K | N40: =D40&"/"&F40 -> 009/S20+ | O40: X-BOB | P40: 27 | Q40: DI1 | R40: 0
...

Sheet 013_DO
A1: TAG | B1: DESCRIPTION | C1: SIGNAL TYPE | D1: CHASSIS &SLOT No | E1: CHANNEL NO. | F1: SIGNAL | G1: MODULE | H1: CONNECTION BOARD | I1: CB TERM. | J1: WIRE COLOUR | K1: WIRE TYPE | L1: WIRE NUMBER | M1: DEVICE TERM. IN | N1: DEVICE | O1: DEVICE TERM. OUT | P1: DEVICE LOCATION | Q1: DEVICE TAG | R1: WIRE COLOUR | S1: WIRE TYPE | T1: WIRE NUMBER | U1: TERMINAL BLOCK | V1: TERM. No. | W1: Loop Type | X1: REV.
A2: B10E-PS-WLT-01:EN | B2: White Lights Enable (Relay) | C2: 24Vdc | D2: {=_xlfn.LET(_xlpm.filepath,CELL("filename",D2),MID(_xlpm.filepath,FIND("]",_xlpm.filepath)+1,3))} -> 013 | E2: 1 | F2: ="DO"&E2&"+" -> DO1+ | G2: X-DO 24 01 | H2: X-CB 009 01 | I2: 1a | J2: Grey | K2: 0.75mm² H05Z-K | L2: =D2&"/"&F2 -> 013/DO1+ | M2: A1 | N2: CON-1 | Q2: B10E-PS-WLT-01 | W2: SEE | X2: 0/1
F3: ="DO"&E2&"-" -> DO1- | I3: 1b | J3: White | K3: 0.75mm² H05Z-K | L3: =D2&"/"&F3 -> 013/DO1- | M3: A2 | W3: DWG 72
F4: 13L+ | J4: Red | K4: 2.5mm² H07Z-K | L4: 13L+ | M4: 1/L1 | O4: 2/T1 | R4: Red | S4: 2.5mm² H07Z-K | T4: CON1/:2 | U4: X-WLT | V4: 1 | Z4: Change wire size
F5: 14L+ | J5: Red | K5: 2.5mm² H07Z-K | L5: 14L+ | M5: 3/L2 | O5: 4/T2 | R5: Red | S5: 2.5mm² H07Z-K | T5: CON1/:4 | U5: X-WLT | V5: 3
F6: 13L- | R6: White | S6: 2.5mm² H07Z-K | T6: 13L- | U6: X-WLT | V6: 2
F7: 14L- | R7: White | S7: 2.5mm² H07Z-K | T7: 14L- | U7: X-WLT | V7: 4
A8: B10E-PS-CUST-01 | B8: HVEE Interlock | C8: 24Vdc | D8: {=_xlfn.LET(_xlpm.filepath,CELL("filename",D8),MID(_xlpm.filepath,FIND("]",_xlpm.filepath)+1,3))} -> 013 | E8: 2 | F8: ="DO"&E8&"+" -> DO2+ | G8: X-DO 24 01 | H8: X-CB 009 01 | I8: 2a | J8: Grey | K8: 0.75mm² H05Z-K | L8: =D8&"/"&F8 -> 013/DO2+ | M8: 4 | N8: CON-6 | O8: 7 | Q8: B10E-PS-CON-11 | R8: Orange | S8: 0.75mm² H05Z-K | T8: =D8&"/"&F8 -> 013/DO2+ | U8: X-INTF07 | V8: 39 | W8: SEE | X8: 0/2 | Z8: Tag change
F9: ="DO"&E8&"-" -> DO2- | I9: 2b | J9: White | K9: 0.75mm² H05Z-K | L9: =D8&"/"&F9 -> 013/DO2- | M9: 2 | N9: (H4116) | O9: 6 | R9: Orange | S9: 0.75mm² H05Z-K | T9: =D8&"/"&F9 -> 013/DO2- | U9: X-INTF07 | V9: 40 | W9: DWG 73
A10: B10E-PS-KEY-01:SOL | B10: Beamline Enable Keyswitch Solenoid | C10: 24Vdc | D10: {=_xlfn.LET(_xlpm.filepath,CELL("filename",D10),MID(_xlpm.filepath,FIND("]",_xlpm.filepath)+1,3))} -> 013 | E10: 3 | F10: ="DO"&E10&"+" -> DO3+ | G10: X-DO 24 01 | H10: X-CB 009 01 | I10: 3a | P10: ZCP | Q10: B10E-PS-KEY-01 | R10: Grey | S10: 0.75mm² H05Z-K | T10: =D10&"/"&F10 -> 013/DO3+ | U10: X-ZCP | V10: 1 | W10: DO1 | X10: 0
F11: ="DO"&E10&"-" -> DO3- | I11: 3b | R11: White | S11: 0.75mm² H05Z-K | T11: =D10&"/"&F11 -> 013/DO3- | U11: X-ZCP | V11: 2
A12: B10E-PS-KEY-02:SOL | B12: Hutch Enable Keyswitch Solenoid | C12: 24Vdc | D12: {=_xlfn.LET(_xlpm.filepath,CELL("filename",D12),MID(_xlpm.filepath,FIND("]",_xlpm.filepath)+1,3))} -> 013 | E12: 4 | F12: ="DO"&E12&"+" -> DO4+ | G12: X-DO 24 01 | H12: X-CB 009 01 | I12: 4a | P12: ZCP | Q12: B10E-PS-KEY-02 | R12: Grey | S12: 0.75mm² H05Z-K | T12: =D12&"/"&F12 -> 013/DO4+ | U12: X-ZCP | V12: 5 | W12: DO1 | X12: 0
F13: ="DO"&E12&"-" -> DO4- | I13: 4b | R13: White | S13: 0.75mm² H05Z-K | T13: =D12&"/"&F13 -> 013/DO4- | U13: X-ZCP | V13: 6
A14: B10E-PS-OR-01:LED | B14: Door Open / Reset Pushbutton LED | C14: 24Vdc | D14: {=_xlfn.LET(_xlpm.filepath,CELL("filename",D14),MID(_xlpm.filepath,FIND("]",_xlpm.filepath)+1,3))} -> 013 | E14: 5 | F14: ="DO"&E14&"+" -> DO5+ | G14: X-DO 24 01 | H14: X-CB 009 01 | I14: 5a | P14: ZCP | Q14: B10E-PS-OR-01 | R14: Grey | S14: 0.75mm² H05Z-K | T14: =D14&"/"&F14 -> 013/DO5+ | U14: X-ZCP | V14: 15 | W14: DO1 | X14: 0
F15: ="DO"&E14&"-" -> DO5- | I15: 5b | R15: White | S15: 0.75mm² H05Z-K | T15: =D14&"/"&F15 -> 013/DO5- | U15: X-ZCP | V15: 16
A16: B10E-PS-ASBF-01:LED | B16: Area Search Button Final LED | C16: 24Vdc | D16: {=_xlfn.LET(_xlpm.filepath,CELL("filename",D16),MID(_xlpm.filepath,FIND("]",_xlpm.filepath)+1,3))} -> 013 | E16: 6 | F16: ="DO"&E16&"+" -> DO6+ | G16: X-DO 24 01 | H16: X-CB 009 01 | I16: 6a | P16: ZCP | Q16: B10E-PS-ASBF-01 | R16: Grey | S16: 0.75mm² H05Z-K | T16: =D16&"/"&F16 -> 013/DO6+ | U16: X-ZCP | V16: 11 | W16: DO1 | X16: 0
F17: ="DO"&E16&"-" -> DO6- | I17: 6b | R17: White | S17: 0.75mm² H05Z-K | T17: =D16&"/"&F17 -> 013/DO6- | U17: X-ZCP | V17: 12
A18: B10E-PS-WLON-01:LED | B18: White Lights Enable Switch LED | C18: 24Vdc | D18: {=_xlfn.LET(_xlpm.filepath,CELL("filename",D18),MID(_xlpm.filepath,FIND("]",_xlpm.filepath)+1,3))} -> 013 | E18: 7 | F18: ="DO"&E18&"+" -> DO7+ | G18: X-DO 24 01 | H18: X-CB 009 01 | I18: 7a | P18: ZCP | Q18: B10E-PS-WLON-01 | R18: Grey | S18: 0.75mm² H05Z-K | T18: =D18&"/"&F18 -> 013/DO7+ | U18: X-ZCP | V18: 27 | W18: DO1 | X18: 0
F19: ="DO"&E18&"-" -> DO7- | I19: 7b | R19: White | S19: 0.75mm² H05Z-K | T19: =D18&"/"&F19 -> 013/DO7- | U19: X-ZCP | V19: 28
A20: B10E-PS-LCTx-01 | B20: Light Curtain Test Function | C20: 24Vdc | D20: {=_xlfn.LET(_xlpm.filepath,CELL("filename",D20),MID(_xlpm.filepath,FIND("]",_xlpm.filepath)+1,3))} -> 013 | E20: 8 | F20: ="DO"&E20&"+" -> DO8+ | G20: X-DO 24 01 | H20: X-CB 009 01 | I20: 8a | P20: EXTERNAL (VIA ZCP) | Q20: B10E-PS-LCTx-01 | R20: Grey | S20: 0.75mm² H05Z-K | T20: =D20&"/"&F20 -> 013/DO8+ | U20: X-ZCP | V20: 35 | W20: DO1 | X20: 0
F21: ="DO"&E20&"-" -> DO8- | I21: 8b | R21: White | S21: 0.75mm² H05Z-K | T21: =D20&"/"&F21 -> 013/DO8- | U21: X-ZCP | V21: 36
A22: B10E-PS-ANNOPN-01:A | B22: Hutch Status Annunciator - OPEN A | C22: 24Vdc | D22: {=_xlfn.LET(_xlpm.filepath,CELL("filename",D22),MID(_xlpm.filepath,FIND("]",_xlpm.filepath)+1,3))} -> 013 | E22: 9 | F22: ="DO"&E22&"+" -> DO9+ | G22: X-DO 24 01 | H22: X-CB 009 01 | I22: 9a | P22: EXTERNAL | Q22: B10E-PS-ANNUN-01 | R22: Grey | S22: 0.75mm² H05Z-K | T22: =D22&"/"&F22 -> 013/DO9+ | U22: X-ANNUN | V22: 1 | W22: DO1 | X22: 0
F23: ="DO"&E22&"-" -> DO9- | I23: 9b | R23: White | S23: 0.75mm² H05Z-K | T23: =D22&"/"&F23 -> 013/DO9- | U23: X-ANNUN | V23: 2
A24: B10E-PS-ANNRES-01:A | B24: Hutch Status Annunciator - RESTRICTED A | C24: 24Vdc | D24: {=_xlfn.LET(_xlpm.filepath,CELL("filename",D24),MID(_xlpm.filepath,FIND("]",_xlpm.filepath)+1,3))} -> 013 | E24: 10 | F24: ="DO"&E24&"+" -> DO10+ | G24: X-DO 24 01 | H24: X-CB 009 01 | I24: 10a | P24: EXTERNAL | Q24: B10E-PS-ANNUN-01 | R24: Grey | S24: 0.75mm² H05Z-K | T24: =D24&"/"&F24 -> 013/DO10+ | U24: X-ANNUN | V24: 5 | W24: DO1 | X24: 0
F25: ="DO"&E24&"-" -> DO10- | I25: 10b | R25: White | S25: 0.75mm² H05Z-K | T25: =D24&"/"&F25 -> 013/DO10- | U25: X-ANNUN | V25: 6
A26: B10E-PS-ANNSTB-01:A | B26: Hutch Status Annunciator - STANDBY A | C26: 24Vdc | D26: {=_xlfn.LET(_xlpm.filepath,CELL("filename",D26),MID(_xlpm.filepath,FIND("]",_xlpm.filepath)+1,3))} -> 013 | E26: 11 | F26: ="DO"&E26&"+" -> DO11+ | G26: X-DO 24 01 | H26: X-CB 009 01 | I26: 11a | P26: EXTERNAL | Q26: B10E-PS-ANNUN-01 | R26: Grey | S26: 0.75mm² H05Z-K | T26: =D26&"/"&F26 -> 013/DO11+ | U26: X-ANNUN | V26: 9 | W26: DO1 | X26: 0
F27: ="DO"&E26&"-" -> DO11- | I27: 11b | R27: White | S27: 0.75mm² H05Z-K | T27: =D26&"/"&F27 -> 013/DO11- | U27: X-ANNUN | V27: 10
A28: B10E-PS-ANNBON-01:A | B28: Hutch Status Annunciator - BEAM ON A | C28: 24Vdc | D28: {=_xlfn.LET(_xlpm.filepath,CELL("filename",D28),MID(_xlpm.filepath,FIND("]",_xlpm.filepath)+1,3))} -> 013 | E28: 12 | F28: ="DO"&E28&"+" -> DO12+ | G28: X-DO 24 01 | H28: X-CB 009 01 | I28: 12a | P28: EXTERNAL | Q28: B10E-PS-ANNUN-01 | R28: Grey | S28: 0.75mm² H05Z-K | T28: =D28&"/"&F28 -> 013/DO12+ | U28: X-ANNUN | V28: 13 | W28: DO1 | X28: 0
F29: ="DO"&E28&"-" -> DO12- | I29: 12b | R29: White | S29: 0.75mm² H05Z-K | T29: =D28&"/"&F29 -> 013/DO12- | U29: X-ANNUN | V29: 14
A30: B10E-PS-SP01-01 | B30: Beacon/Sounder 01 Message 1 (LSB) | C30: 24Vdc | D30: {=_xlfn.LET(_xlpm.filepath,CELL("filename",D30),MID(_xlpm.filepath,FIND("]",_xlpm.filepath)+1,3))} -> 013 | E30: 13 | F30: ="DO"&E30&"+" -> DO13+ | G30: X-DO 24 01 | H30: X-CB 009 01 | I30: 13a | P30: HUTCH | Q30: B10E-PS-SP-01 | R30: Grey | S30: 0.75mm² H05Z-K | T30: =D30&"/"&F30 -> 013/DO13+ | U30: X-SP01 | V30: 1 | W30: DO1 | X30: 0
F31: ="DO"&E30&"-" -> DO13- | I31: 13b | R31: White | S31: 0.75mm² H05Z-K | T31: =D30&"/"&F31 -> 013/DO13- | U31: X-SP01 | V31: 2
A32: B10E-PS-SP02-01 | B32: Beacon/Sounder 01 Message 2 (MSB) | C32: 24Vdc | D32: {=_xlfn.LET(_xlpm.filepath,CELL("filename",D32),MID(_xlpm.filepath,FIND("]",_xlpm.filepath)+1,3))} -> 013 | E32: 14 | F32: ="DO"&E32&"+" -> DO14+ | G32: X-DO 24 01 | H32: X-CB 009 01 | I32: 14a | P32: HUTCH | Q32: B10E-PS-SP-01 | R32: Grey | S32: 0.75mm² H05Z-K | T32: =D32&"/"&F32 -> 013/DO14+ | U32: X-SP01 | V32: 3 | W32: DO1 | X32: 0
F33: ="DO"&E32&"-" -> DO14- | I33: 14b | R33: White | S33: 0.75mm² H05Z-K | T33: =D32&"/"&F33 -> 013/DO14- | U33: X-SP01 | V33: 4
A34: B10E-PS-SP03-01 | B34: Beacon/Sounder 01 Strobe | C34: 24Vdc | D34: {=_xlfn.LET(_xlpm.filepath,CELL("filename",D34),MID(_xlpm.filepath,FIND("]",_xlpm.filepath)+1,3))} -> 013 | E34: 15 | F34: ="DO"&E34&"+" -> DO15+ | G34: X-DO 24 01 | H34: X-CB 009 01 | I34: 15a | P34: HUTCH | Q34: B10E-PS-SP-01 | R34: Grey | S34: 0.75mm² H05Z-K | T34: =D34&"/"&F34 -> 013/DO15+ | U34: X-SP01 | V34: 5 | W34: DO1 | X34: 0
F35: ="DO"&E34&"-" -> DO15- | I35: 15b | R35: White | S35: 0.75mm² H05Z-K | T35: =D34&"/"&F35 -> 013/DO15- | U35: X-SP01 | V35: 6
A36: B10E-PS-SOVLN2-01 | B36: Liquid Nitrogen Shuttoff Valve | C36: 24Vdc | D36: {=_xlfn.LET(_xlpm.filepath,CELL("filename",D36),MID(_xlpm.filepath,FIND("]",_xlpm.filepath)+1,3))} -> 013 | E36: 16 | F36: ="DO"&E36&"+" -> DO16+ | G36: X-DO 24 01 | H36: X-CB 009 01 | I36: 16a | P36: EXTERNAL | Q36: B10E-PS-SOVLN2-01 | R36: Grey | S36: 0.75mm² H05Z-K | T36: =D36&"/"&F36 -> 013/DO16+ | U36: X-SOVLN2 | V36: 1 | W36: DO1 | X36: 0
F37: ="DO"&E36&"-" -> DO16- | I37: 16b | R37: White | S37: 0.75mm² H05Z-K | T37: =D36&"/"&F37 -> 013/DO16- | U37: X-SOVLN2 | V37: 2
A38: B10E-PS-SP01-04 | B38: O2/SF6 Healthy Beacon 01 (Green LED) | C38: 24Vdc | D38: {=_xlfn.LET(_xlpm.filepath,CELL("filename",D38),MID(_xlpm.filepath,FIND("]",_xlpm.filepath)+1,3))} -> 013 | E38: 17 | F38: ="DO"&E38&"+" -> DO17+ | G38: X-DO 24 01 | H38: X-CB 009 01 | I38: 17a | P38: HUTCH | Q38: B10E-PS-SP-04 | R38: Grey | S38: 0.75mm² H05Z-K | T38: =D38&"/"&F38 -> 013/DO17+ | U38: X-SP | V38: 1 | W38: DO1 | X38: 0
F39: ="DO"&E38&"-" -> DO17- | I39: 17b | R39: White | S39: 0.75mm² H05Z-K | T39: =D38&"/"&F39 -> 013/DO17- | U39: X-SP | V39: 2
A40: B10E-PS-SP02-04 | B40: O2/SF6 Alarm Beacon 01 (Red LED) | C40: 24Vdc | D40: {=_xlfn.LET(_xlpm.filepath,CELL("filename",D40),MID(_xlpm.filepath,FIND("]",_xlpm.filepath)+1,3))} -> 013 | E40: 18 | F40: ="DO"&E40&"+" -> DO18+ | G40: X-DO 24 01 | H40: X-CB 009 01 | I40: 18a | P40: HUTCH | Q40: B10E-PS-SP-04 | R40: Grey | S40: 0.75mm² H05Z-K | T40: =D40&"/"&F40 -> 013/DO18+ | U40: X-SP | V40: 3 | W40: DO1 | X40: 0
...

Sheet 014_DO
A1: TAG | B1: DESCRIPTION | C1: SIGNAL TYPE | D1: CHASSIS &SLOT No | E1: Channel. No. | F1: Signal | G1: MODULE | H1: CONNECTION BOARD | I1: CB TERM. | J1: DEVICE LOCATION | K1: DEVICE TAG | L1: WIRE COLOUR | M1: WIRE TYPE | N1: WIRE NUMBER | O1: TERMINAL BLOCK | P1: TERM. No. | Q1: Loop Type | R1: REV.
A2: B10E-PS-ASB-01:LED | B2: Area Search Pushbutton LED 01 | C2: 24Vdc | D2: {=_xlfn.LET(_xlpm.filepath,CELL("filename",D2),MID(_xlpm.filepath,FIND("]",_xlpm.filepath)+1,3))} -> 014 | E2: 1 | F2: ="DO"&E2&"+" -> DO1+ | G2: X-DO 24 01 | H2: X-CB 009 01 | I2: 1a | J2: HUTCH | K2: B10E-PS-ASB-01 | L2: Grey | M2: 0.75mm² H05Z-K | N2: =D2&"/"&F2 -> 014/DO1+ | O2: X-ASB | P2: 3 | Q2: DO1 | R2: 0
F3: ="DO"&E2&"-" -> DO1- | I3: 1b | L3: White | M3: 0.75mm² H05Z-K | N3: =D2&"/"&F3 -> 014/DO1- | O3: X-ASB | P3: 4
A4: B10E-PS-ASB-02:LED | B4: Area Search Pushbutton LED 02 | C4: 24Vdc | D4: {=_xlfn.LET(_xlpm.filepath,CELL("filename",D4),MID(_xlpm.filepath,FIND("]",_xlpm.filepath)+1,3))} -> 014 | E4: 2 | F4: ="DO"&E4&"+" -> DO2+ | G4: X-DO 24 01 | H4: X-CB 009 01 | I4: 2a | J4: HUTCH | K4: B10E-PS-ASB-02 | L4: Grey | M4: 0.75mm² H05Z-K | N4: =D4&"/"&F4 -> 014/DO2+ | O4: X-ASB | P4: 7 | Q4: DO1 | R4: 0
F5: ="DO"&E4&"-" -> DO2- | I5: 2b | L5: White | M5: 0.75mm² H05Z-K | N5: =D4&"/"&F5 -> 014/DO2- | O5: X-ASB | P5: 8
A6: B10E-PS-ASB-03:LED | B6: Area Search Pushbutton LED 03 | C6: 24Vdc | D6: {=_xlfn.LET(_xlpm.filepath,CELL("filename",D6),MID(_xlpm.filepath,FIND("]",_xlpm.filepath)+1,3))} -> 014 | E6: 3 | F6: ="DO"&E6&"+" -> DO3+ | G6: X-DO 24 01 | H6: X-CB 009 01 | I6: 3a | J6: HUTCH | K6: B10E-PS-ASB-03 | L6: Grey | M6: 0.75mm² H05Z-K | N6: =D6&"/"&F6 -> 014/DO3+ | O6: X-ASB | P6: 11 | Q6: DO1 | R6: 0
F7: ="DO"&E6&"-" -> DO3- | I7: 3b | L7: White | M7: 0.75mm² H05Z-K | N7: =D6&"/"&F7 -> 014/DO3- | O7: X-ASB | P7: 12
A8: B10E-PS-ASB-04:LED | B8: Area Search Pushbutton LED 04 | C8: 24Vdc | D8: {=_xlfn.LET(_xlpm.filepath,CELL("filename",D8),MID(_xlpm.filepath,FIND("]",_xlpm.filepath)+1,3))} -> 014 | E8: 4 | F8: ="DO"&E8&"+" -> DO4+ | G8: X-DO 24 01 | H8: X-CB 009 01 | I8: 4a | J8: HUTCH | K8: B10E-PS-ASB-04 | L8: Grey | M8: 0.75mm² H05Z-K | N8: =D8&"/"&F8 -> 014/DO4+ | O8: X-ASB | P8: 15 | Q8: DO1 | R8: 0
F9: ="DO"&E8&"-" -> DO4- | I9: 4b | L9: White | M9: 0.75mm² H05Z-K | N9: =D8&"/"&F9 -> 014/DO4- | O9: X-ASB | P9: 16
A10: B10E-PS-SP01-02 | B10: Beacon/Sounder 02 Message 1 (LSB) | C10: 24Vdc | D10: {=_xlfn.LET(_xlpm.filepath,CELL("filename",D10),MID(_xlpm.filepath,FIND("]",_xlpm.filepath)+1,3))} -> 014 | E10: 5 | F10: ="DO"&E10&"+" -> DO5+ | G10: X-DO 24 01 | H10: X-CB 009 01 | I10: 5a | J10: HUTCH | K10: B10E-PS-SP-02 | L10: Grey | M10: 0.75mm² H05Z-K | N10: =D10&"/"&F10 -> 014/DO5+ | O10: X-SP02 | P10: 1 | Q10: DO1 | R10: 0
F11: ="DO"&E10&"-" -> DO5- | I11: 5b | L11: White | M11: 0.75mm² H05Z-K | N11: =D10&"/"&F11 -> 014/DO5- | O11: X-SP02 | P11: 2
A12: B10E-PS-SP02-02 | B12: Beacon/Sounder 02 Message 2 (MSB) | C12: 24Vdc | D12: {=_xlfn.LET(_xlpm.filepath,CELL("filename",D12),MID(_xlpm.filepath,FIND("]",_xlpm.filepath)+1,3))} -> 014 | E12: 6 | F12: ="DO"&E12&"+" -> DO6+ | G12: X-DO 24 01 | H12: X-CB 009 01 | I12: 6a | J12: HUTCH | K12: B10E-PS-SP-02 | L12: Grey | M12: 0.75mm² H05Z-K | N12: =D12&"/"&F12 -> 014/DO6+ | O12: X-SP02 | P12: 3 | Q12: DO1 | R12: 0
F13: ="DO"&E12&"-" -> DO6- | I13: 6b | L13: White | M13: 0.75mm² H05Z-K | N13: =D12&"/"&F13 -> 014/DO6- | O13: X-SP02 | P13: 4
A14: B10E-PS-SP03-02 | B14: Beacon/Sounder 02 Strobe | C14: 24Vdc | D14: {=_xlfn.LET(_xlpm.filepath,CELL("filename",D14),MID(_xlpm.filepath,FIND("]",_xlpm.filepath)+1,3))} -> 014 | E14: 7 | F14: ="DO"&E14&"+" -> DO7+ | G14: X-DO 24 01 | H14: X-CB 009 01 | I14: 7a | J14: HUTCH | K14: B10E-PS-SP-02 | L14: Grey | M14: 0.75mm² H05Z-K | N14: =D14&"/"&F14 -> 014/DO7+ | O14: X-SP02 | P14: 5 | Q14: DO1 | R14: 0
F15: ="DO"&E14&"-" -> DO7- | I15: 7b | L15: White | M15: 0.75mm² H05Z-K | N15: =D14&"/"&F15 -> 014/DO7- | O15: X-SP02 | P15: 6
A16: ="SPDO-"&D16&"/"&E16 -> SPDO-014/8 | B16: Wired Spare Output | C16: 24Vdc | D16: {=_xlfn.LET(_xlpm.filepath,CELL("filename",D16),MID(_xlpm.filepath,FIND("]",_xlpm.filepath)+1,3))} -> 014 | E16: 8 | F16: ="DO"&E16&"+" -> DO8+ | G16: X-DO 24 01 | H16: X-CB 009 01 | I16: 8a | L16: Grey | M16: 0.75mm² H05Z-K | N16: =D16&"/"&F16 -> 014/DO8+ | O16: X-SPDO | P16: 13 | Q16: DO1 | R16: 0
F17: ="DO"&E16&"-" -> DO8- | I17: 8b | L17: White | M17: 0.75mm² H05Z-K | N17: =D16&"/"&F17 -> 014/DO8- | O17: X-SPDO | P17: 14
A18: B10E-PS-ANNOPN-01:B | B18: Hutch Status Annunciator - OPEN B | C18: 24Vdc | D18: {=_xlfn.LET(_xlpm.filepath,CELL("filename",D18),MID(_xlpm.filepath,FIND("]",_xlpm.filepath)+1,3))} -> 014 | E18: 9 | F18: ="DO"&E18&"+" -> DO9+ | G18: X-DO 24 01 | H18: X-CB 009 01 | I18: 9a | J18: EXTERNAL | K18: B10E-PS-ANNUN-01 | L18: Grey | M18: 0.75mm² H05Z-K | N18: =D18&"/"&F18 -> 014/DO9+ | O18: X-ANNUN | P18: 3 | Q18: DO1 | R18: 0
